Watching for file changes with StatReloader
Watching for file changes with StatReloader
Watching for file changes with StatReloader
Internal Server Error: /mr/pesquisar_atendimento
Traceback (most recent call last):
  File "/home/wercules/.local/share/virtualenvs/medreport-3oUkA-aL/lib/python3.6/site-packages/django/utils/datastructures.py", line 78, in __getitem__
    list_ = super().__getitem__(key)
KeyError: 'id'

During handling of the above exception, another exception occurred:

Traceback (most recent call last):
  File "/home/wercules/.local/share/virtualenvs/medreport-3oUkA-aL/lib/python3.6/site-packages/django/core/handlers/exception.py", line 34, in inner
    response = get_response(request)
  File "/home/wercules/.local/share/virtualenvs/medreport-3oUkA-aL/lib/python3.6/site-packages/django/core/handlers/base.py", line 115, in _get_response
    response = self.process_exception_by_middleware(e, request)
  File "/home/wercules/.local/share/virtualenvs/medreport-3oUkA-aL/lib/python3.6/site-packages/django/core/handlers/base.py", line 113, in _get_response
    response = wrapped_callback(request, *callback_args, **callback_kwargs)
  File "/home/wercules/medreport/mrApp/views.py", line 76, in pesquisar_atendimento
    atendimento = Atendimento.objects.filter(paciente__id=request.POST['id'])
  File "/home/wercules/.local/share/virtualenvs/medreport-3oUkA-aL/lib/python3.6/site-packages/django/utils/datastructures.py", line 80, in __getitem__
    raise MultiValueDictKeyError(key)
django.utils.datastructures.MultiValueDictKeyError: 'id'
[02/Jun/2019 21:55:49] "GET /mr/pesquisar_atendimento?csrfmiddlewaretoken=NCchIdGa5HjTMGn81Jl8OTNe3cS2Yn0ZzpvPbmzI9MbEY8OXyw0QyCgM2B7psP1D&paciente_id=1 HTTP/1.1" 500 76712
/home/wercules/medreport/mrApp/views.py changed, reloading.
Performing system checks...

System check identified no issues (0 silenced).
June 02, 2019 - 21:55:33
Django version 2.2.1, using settings 'mrProject.settings'
Starting development server at http://cardiobemestar.com.br:8000/
Quit the server with CONTROL-C.
Watching for file changes with StatReloader
/home/wercules/medreport/mrApp/views.py changed, reloading.
Performing system checks...

System check identified no issues (0 silenced).
June 02, 2019 - 21:56:33
Django version 2.2.1, using settings 'mrProject.settings'
Starting development server at http://cardiobemestar.com.br:8000/
Quit the server with CONTROL-C.
Watching for file changes with StatReloader
/home/wercules/medreport/mrApp/views.py changed, reloading.
Performing system checks...

System check identified no issues (0 silenced).
June 02, 2019 - 21:56:46
Django version 2.2.1, using settings 'mrProject.settings'
Starting development server at http://cardiobemestar.com.br:8000/
Quit the server with CONTROL-C.
Watching for file changes with StatReloader
Internal Server Error: /mr/pesquisar_atendimento
Traceback (most recent call last):
  File "/home/wercules/.local/share/virtualenvs/medreport-3oUkA-aL/lib/python3.6/site-packages/django/utils/datastructures.py", line 78, in __getitem__
    list_ = super().__getitem__(key)
KeyError: 'id'

During handling of the above exception, another exception occurred:

Traceback (most recent call last):
  File "/home/wercules/.local/share/virtualenvs/medreport-3oUkA-aL/lib/python3.6/site-packages/django/core/handlers/exception.py", line 34, in inner
    response = get_response(request)
  File "/home/wercules/.local/share/virtualenvs/medreport-3oUkA-aL/lib/python3.6/site-packages/django/core/handlers/base.py", line 115, in _get_response
    response = self.process_exception_by_middleware(e, request)
  File "/home/wercules/.local/share/virtualenvs/medreport-3oUkA-aL/lib/python3.6/site-packages/django/core/handlers/base.py", line 113, in _get_response
    response = wrapped_callback(request, *callback_args, **callback_kwargs)
  File "/home/wercules/medreport/mrApp/views.py", line 76, in pesquisar_atendimento
    atendimento = request.POST['id']
  File "/home/wercules/.local/share/virtualenvs/medreport-3oUkA-aL/lib/python3.6/site-packages/django/utils/datastructures.py", line 80, in __getitem__
    raise MultiValueDictKeyError(key)
django.utils.datastructures.MultiValueDictKeyError: 'id'
[02/Jun/2019 21:57:13] "GET /mr/pesquisar_atendimento?csrfmiddlewaretoken=NCchIdGa5HjTMGn81Jl8OTNe3cS2Yn0ZzpvPbmzI9MbEY8OXyw0QyCgM2B7psP1D&paciente_id=1 HTTP/1.1" 500 76613
/home/wercules/medreport/mrApp/views.py changed, reloading.
Performing system checks...

System check identified no issues (0 silenced).
June 02, 2019 - 21:56:52
Django version 2.2.1, using settings 'mrProject.settings'
Starting development server at http://cardiobemestar.com.br:8000/
Quit the server with CONTROL-C.
Watching for file changes with StatReloader
Internal Server Error: /mr/pesquisar_atendimento
Traceback (most recent call last):
  File "/home/wercules/.local/share/virtualenvs/medreport-3oUkA-aL/lib/python3.6/site-packages/django/utils/datastructures.py", line 78, in __getitem__
    list_ = super().__getitem__(key)
KeyError: 'paciente_id'

During handling of the above exception, another exception occurred:

Traceback (most recent call last):
  File "/home/wercules/.local/share/virtualenvs/medreport-3oUkA-aL/lib/python3.6/site-packages/django/core/handlers/exception.py", line 34, in inner
    response = get_response(request)
  File "/home/wercules/.local/share/virtualenvs/medreport-3oUkA-aL/lib/python3.6/site-packages/django/core/handlers/base.py", line 115, in _get_response
    response = self.process_exception_by_middleware(e, request)
  File "/home/wercules/.local/share/virtualenvs/medreport-3oUkA-aL/lib/python3.6/site-packages/django/core/handlers/base.py", line 113, in _get_response
    response = wrapped_callback(request, *callback_args, **callback_kwargs)
  File "/home/wercules/medreport/mrApp/views.py", line 76, in pesquisar_atendimento
    atendimento = request.POST['paciente_id']
  File "/home/wercules/.local/share/virtualenvs/medreport-3oUkA-aL/lib/python3.6/site-packages/django/utils/datastructures.py", line 80, in __getitem__
    raise MultiValueDictKeyError(key)
django.utils.datastructures.MultiValueDictKeyError: 'paciente_id'
[02/Jun/2019 21:59:13] "GET /mr/pesquisar_atendimento?csrfmiddlewaretoken=NCchIdGa5HjTMGn81Jl8OTNe3cS2Yn0ZzpvPbmzI9MbEY8OXyw0QyCgM2B7psP1D&paciente_id=1 HTTP/1.1" 500 76703
[02/Jun/2019 21:59:51] "POST /mr/procurar_paciente HTTP/1.1" 200 2156
Not Found: /resources/demos/style.css
[02/Jun/2019 21:59:52] "GET /resources/demos/style.css HTTP/1.1" 404 2241
[02/Jun/2019 21:59:52] "GET /static/css/style.css HTTP/1.1" 304 0
[02/Jun/2019 21:59:52] "GET /static/js/main.js HTTP/1.1" 304 0
Internal Server Error: /mr/pesquisar_atendimento
Traceback (most recent call last):
  File "/home/wercules/.local/share/virtualenvs/medreport-3oUkA-aL/lib/python3.6/site-packages/django/utils/datastructures.py", line 78, in __getitem__
    list_ = super().__getitem__(key)
KeyError: 'paciente_id'

During handling of the above exception, another exception occurred:

Traceback (most recent call last):
  File "/home/wercules/.local/share/virtualenvs/medreport-3oUkA-aL/lib/python3.6/site-packages/django/core/handlers/exception.py", line 34, in inner
    response = get_response(request)
  File "/home/wercules/.local/share/virtualenvs/medreport-3oUkA-aL/lib/python3.6/site-packages/django/core/handlers/base.py", line 115, in _get_response
    response = self.process_exception_by_middleware(e, request)
  File "/home/wercules/.local/share/virtualenvs/medreport-3oUkA-aL/lib/python3.6/site-packages/django/core/handlers/base.py", line 113, in _get_response
    response = wrapped_callback(request, *callback_args, **callback_kwargs)
  File "/home/wercules/medreport/mrApp/views.py", line 76, in pesquisar_atendimento
    atendimento = request.POST['paciente_id']
  File "/home/wercules/.local/share/virtualenvs/medreport-3oUkA-aL/lib/python3.6/site-packages/django/utils/datastructures.py", line 80, in __getitem__
    raise MultiValueDictKeyError(key)
django.utils.datastructures.MultiValueDictKeyError: 'paciente_id'
[02/Jun/2019 21:59:55] "GET /mr/pesquisar_atendimento?csrfmiddlewaretoken=Dji5nOWEqaWMXVBulRfAj4Lhwgug9zmGp6BDQXPcufOx9n2jSEUi3NePvFJDD1nk&paciente_id=1 HTTP/1.1" 500 76703
Internal Server Error: /mr/pesquisar_atendimento
Traceback (most recent call last):
  File "/home/wercules/.local/share/virtualenvs/medreport-3oUkA-aL/lib/python3.6/site-packages/django/utils/datastructures.py", line 78, in __getitem__
    list_ = super().__getitem__(key)
KeyError: 'paciente_id'

During handling of the above exception, another exception occurred:

Traceback (most recent call last):
  File "/home/wercules/.local/share/virtualenvs/medreport-3oUkA-aL/lib/python3.6/site-packages/django/core/handlers/exception.py", line 34, in inner
    response = get_response(request)
  File "/home/wercules/.local/share/virtualenvs/medreport-3oUkA-aL/lib/python3.6/site-packages/django/core/handlers/base.py", line 115, in _get_response
    response = self.process_exception_by_middleware(e, request)
  File "/home/wercules/.local/share/virtualenvs/medreport-3oUkA-aL/lib/python3.6/site-packages/django/core/handlers/base.py", line 113, in _get_response
    response = wrapped_callback(request, *callback_args, **callback_kwargs)
  File "/home/wercules/medreport/mrApp/views.py", line 76, in pesquisar_atendimento
    atendimento = request.POST['paciente_id']
  File "/home/wercules/.local/share/virtualenvs/medreport-3oUkA-aL/lib/python3.6/site-packages/django/utils/datastructures.py", line 80, in __getitem__
    raise MultiValueDictKeyError(key)
django.utils.datastructures.MultiValueDictKeyError: 'paciente_id'
[02/Jun/2019 22:00:36] "GET /mr/pesquisar_atendimento?csrfmiddlewaretoken=Dji5nOWEqaWMXVBulRfAj4Lhwgug9zmGp6BDQXPcufOx9n2jSEUi3NePvFJDD1nk&paciente_id=1 HTTP/1.1" 500 76703
Not Found: /favicon.ico
[02/Jun/2019 22:00:38] "GET /favicon.ico HTTP/1.1" 404 2199
[02/Jun/2019 22:05:34] "GET /static/css/style.css HTTP/1.1" 200 532
Not Found: /resources/demos/style.css
[02/Jun/2019 22:05:34] "GET /resources/demos/style.css HTTP/1.1" 404 2241
[02/Jun/2019 22:05:36] "POST /mr/procurar_paciente HTTP/1.1" 200 2156
Not Found: /resources/demos/style.css
[02/Jun/2019 22:05:36] "GET /resources/demos/style.css HTTP/1.1" 404 2241
Internal Server Error: /mr/pesquisar_atendimento
Traceback (most recent call last):
  File "/home/wercules/.local/share/virtualenvs/medreport-3oUkA-aL/lib/python3.6/site-packages/django/utils/datastructures.py", line 78, in __getitem__
    list_ = super().__getitem__(key)
KeyError: 'paciente_id'

During handling of the above exception, another exception occurred:

Traceback (most recent call last):
  File "/home/wercules/.local/share/virtualenvs/medreport-3oUkA-aL/lib/python3.6/site-packages/django/core/handlers/exception.py", line 34, in inner
    response = get_response(request)
  File "/home/wercules/.local/share/virtualenvs/medreport-3oUkA-aL/lib/python3.6/site-packages/django/core/handlers/base.py", line 115, in _get_response
    response = self.process_exception_by_middleware(e, request)
  File "/home/wercules/.local/share/virtualenvs/medreport-3oUkA-aL/lib/python3.6/site-packages/django/core/handlers/base.py", line 113, in _get_response
    response = wrapped_callback(request, *callback_args, **callback_kwargs)
  File "/home/wercules/medreport/mrApp/views.py", line 76, in pesquisar_atendimento
    atendimento = request.POST['paciente_id']
  File "/home/wercules/.local/share/virtualenvs/medreport-3oUkA-aL/lib/python3.6/site-packages/django/utils/datastructures.py", line 80, in __getitem__
    raise MultiValueDictKeyError(key)
django.utils.datastructures.MultiValueDictKeyError: 'paciente_id'
[02/Jun/2019 22:05:41] "GET /mr/pesquisar_atendimento?csrfmiddlewaretoken=56zXVdx84l9thiVP1GY0v22vLT4gynVHRTSvomqG8q1etKmEytDIfLv3KijD2PWl&paciente_id=1 HTTP/1.1" 500 76703
/home/wercules/medreport/mrApp/views.py changed, reloading.
Performing system checks...

System check identified no issues (0 silenced).
June 02, 2019 - 21:59:09
Django version 2.2.1, using settings 'mrProject.settings'
Starting development server at http://cardiobemestar.com.br:8000/
Quit the server with CONTROL-C.
Watching for file changes with StatReloader
[02/Jun/2019 22:09:00] "POST /mr/procurar_paciente HTTP/1.1" 200 2165
[02/Jun/2019 22:09:01] "GET /static/css/style.css HTTP/1.1" 304 0
Not Found: /resources/demos/style.css
[02/Jun/2019 22:09:01] "GET /static/js/main.js HTTP/1.1" 304 0
[02/Jun/2019 22:09:01] "GET /resources/demos/style.css HTTP/1.1" 404 2241
Internal Server Error: /mr/pesquisar_atendimento
Traceback (most recent call last):
  File "/home/wercules/.local/share/virtualenvs/medreport-3oUkA-aL/lib/python3.6/site-packages/django/utils/datastructures.py", line 78, in __getitem__
    list_ = super().__getitem__(key)
KeyError: 'nome'

During handling of the above exception, another exception occurred:

Traceback (most recent call last):
  File "/home/wercules/.local/share/virtualenvs/medreport-3oUkA-aL/lib/python3.6/site-packages/django/core/handlers/exception.py", line 34, in inner
    response = get_response(request)
  File "/home/wercules/.local/share/virtualenvs/medreport-3oUkA-aL/lib/python3.6/site-packages/django/core/handlers/base.py", line 115, in _get_response
    response = self.process_exception_by_middleware(e, request)
  File "/home/wercules/.local/share/virtualenvs/medreport-3oUkA-aL/lib/python3.6/site-packages/django/core/handlers/base.py", line 113, in _get_response
    response = wrapped_callback(request, *callback_args, **callback_kwargs)
  File "/home/wercules/medreport/mrApp/views.py", line 76, in pesquisar_atendimento
    atendimento = request.POST['nome']
  File "/home/wercules/.local/share/virtualenvs/medreport-3oUkA-aL/lib/python3.6/site-packages/django/utils/datastructures.py", line 80, in __getitem__
    raise MultiValueDictKeyError(key)
django.utils.datastructures.MultiValueDictKeyError: 'nome'
[02/Jun/2019 22:09:04] "GET /mr/pesquisar_atendimento?csrfmiddlewaretoken=1ku76lZLQ9Q182CJcWev9fBH7lyDpg95N7NFzuSjUeIMku3yJJTdTY4f6KN0TIaJ&nome=Wercules+Oliveira HTTP/1.1" 500 76705
[02/Jun/2019 22:11:17] "POST /mr/procurar_paciente HTTP/1.1" 200 2035
Not Found: /resources/demos/style.css
[02/Jun/2019 22:11:18] "GET /resources/demos/style.css HTTP/1.1" 404 2241
[02/Jun/2019 22:11:18] "GET /static/css/style.css HTTP/1.1" 304 0
[02/Jun/2019 22:11:18] "GET /static/js/main.js HTTP/1.1" 304 0
Internal Server Error: /mr/pesquisar_atendimento
Traceback (most recent call last):
  File "/home/wercules/.local/share/virtualenvs/medreport-3oUkA-aL/lib/python3.6/site-packages/django/utils/datastructures.py", line 78, in __getitem__
    list_ = super().__getitem__(key)
KeyError: 'nome'

During handling of the above exception, another exception occurred:

Traceback (most recent call last):
  File "/home/wercules/.local/share/virtualenvs/medreport-3oUkA-aL/lib/python3.6/site-packages/django/core/handlers/exception.py", line 34, in inner
    response = get_response(request)
  File "/home/wercules/.local/share/virtualenvs/medreport-3oUkA-aL/lib/python3.6/site-packages/django/core/handlers/base.py", line 115, in _get_response
    response = self.process_exception_by_middleware(e, request)
  File "/home/wercules/.local/share/virtualenvs/medreport-3oUkA-aL/lib/python3.6/site-packages/django/core/handlers/base.py", line 113, in _get_response
    response = wrapped_callback(request, *callback_args, **callback_kwargs)
  File "/home/wercules/medreport/mrApp/views.py", line 76, in pesquisar_atendimento
    atendimento = request.POST['nome']
  File "/home/wercules/.local/share/virtualenvs/medreport-3oUkA-aL/lib/python3.6/site-packages/django/utils/datastructures.py", line 80, in __getitem__
    raise MultiValueDictKeyError(key)
django.utils.datastructures.MultiValueDictKeyError: 'nome'
[02/Jun/2019 22:11:20] "GET /mr/pesquisar_atendimento?paciente_id=1 HTTP/1.1" 500 75809
[02/Jun/2019 22:11:30] "POST /mr/procurar_paciente HTTP/1.1" 200 2035
Not Found: /resources/demos/style.css
[02/Jun/2019 22:11:31] "GET /resources/demos/style.css HTTP/1.1" 404 2241
Internal Server Error: /mr/pesquisar_atendimento
Traceback (most recent call last):
  File "/home/wercules/.local/share/virtualenvs/medreport-3oUkA-aL/lib/python3.6/site-packages/django/utils/datastructures.py", line 78, in __getitem__
    list_ = super().__getitem__(key)
KeyError: 'nome'

During handling of the above exception, another exception occurred:

Traceback (most recent call last):
  File "/home/wercules/.local/share/virtualenvs/medreport-3oUkA-aL/lib/python3.6/site-packages/django/core/handlers/exception.py", line 34, in inner
    response = get_response(request)
  File "/home/wercules/.local/share/virtualenvs/medreport-3oUkA-aL/lib/python3.6/site-packages/django/core/handlers/base.py", line 115, in _get_response
    response = self.process_exception_by_middleware(e, request)
  File "/home/wercules/.local/share/virtualenvs/medreport-3oUkA-aL/lib/python3.6/site-packages/django/core/handlers/base.py", line 113, in _get_response
    response = wrapped_callback(request, *callback_args, **callback_kwargs)
  File "/home/wercules/medreport/mrApp/views.py", line 76, in pesquisar_atendimento
    atendimento = request.POST['nome']
  File "/home/wercules/.local/share/virtualenvs/medreport-3oUkA-aL/lib/python3.6/site-packages/django/utils/datastructures.py", line 80, in __getitem__
    raise MultiValueDictKeyError(key)
django.utils.datastructures.MultiValueDictKeyError: 'nome'
[02/Jun/2019 22:11:33] "GET /mr/pesquisar_atendimento?paciente_id=1 HTTP/1.1" 500 75809
/home/wercules/medreport/mrApp/views.py changed, reloading.
Performing system checks...

System check identified no issues (0 silenced).
June 02, 2019 - 22:08:55
Django version 2.2.1, using settings 'mrProject.settings'
Starting development server at http://cardiobemestar.com.br:8000/
Quit the server with CONTROL-C.
Watching for file changes with StatReloader
/home/wercules/medreport/mrApp/views.py changed, reloading.
Performing system checks...

System check identified no issues (0 silenced).
June 02, 2019 - 22:11:58
Django version 2.2.1, using settings 'mrProject.settings'
Starting development server at http://cardiobemestar.com.br:8000/
Quit the server with CONTROL-C.
Watching for file changes with StatReloader
[02/Jun/2019 22:12:32] "POST /mr/procurar_paciente HTTP/1.1" 200 2035
Not Found: /resources/demos/style.css
[02/Jun/2019 22:12:32] "GET /resources/demos/style.css HTTP/1.1" 404 2241
Internal Server Error: /mr/pesquisar_atendimento
Traceback (most recent call last):
  File "/home/wercules/.local/share/virtualenvs/medreport-3oUkA-aL/lib/python3.6/site-packages/django/utils/datastructures.py", line 78, in __getitem__
    list_ = super().__getitem__(key)
KeyError: 'paciente_id'

During handling of the above exception, another exception occurred:

Traceback (most recent call last):
  File "/home/wercules/.local/share/virtualenvs/medreport-3oUkA-aL/lib/python3.6/site-packages/django/core/handlers/exception.py", line 34, in inner
    response = get_response(request)
  File "/home/wercules/.local/share/virtualenvs/medreport-3oUkA-aL/lib/python3.6/site-packages/django/core/handlers/base.py", line 115, in _get_response
    response = self.process_exception_by_middleware(e, request)
  File "/home/wercules/.local/share/virtualenvs/medreport-3oUkA-aL/lib/python3.6/site-packages/django/core/handlers/base.py", line 113, in _get_response
    response = wrapped_callback(request, *callback_args, **callback_kwargs)
  File "/home/wercules/medreport/mrApp/views.py", line 76, in pesquisar_atendimento
    atendimento = request.POST['paciente_id']
  File "/home/wercules/.local/share/virtualenvs/medreport-3oUkA-aL/lib/python3.6/site-packages/django/utils/datastructures.py", line 80, in __getitem__
    raise MultiValueDictKeyError(key)
django.utils.datastructures.MultiValueDictKeyError: 'paciente_id'
[02/Jun/2019 22:12:35] "GET /mr/pesquisar_atendimento?paciente_id=1 HTTP/1.1" 500 75879
Internal Server Error: /mr/pesquisar_atendimento
Traceback (most recent call last):
  File "/home/wercules/.local/share/virtualenvs/medreport-3oUkA-aL/lib/python3.6/site-packages/django/utils/datastructures.py", line 78, in __getitem__
    list_ = super().__getitem__(key)
KeyError: 'paciente_id'

During handling of the above exception, another exception occurred:

Traceback (most recent call last):
  File "/home/wercules/.local/share/virtualenvs/medreport-3oUkA-aL/lib/python3.6/site-packages/django/core/handlers/exception.py", line 34, in inner
    response = get_response(request)
  File "/home/wercules/.local/share/virtualenvs/medreport-3oUkA-aL/lib/python3.6/site-packages/django/core/handlers/base.py", line 115, in _get_response
    response = self.process_exception_by_middleware(e, request)
  File "/home/wercules/.local/share/virtualenvs/medreport-3oUkA-aL/lib/python3.6/site-packages/django/core/handlers/base.py", line 113, in _get_response
    response = wrapped_callback(request, *callback_args, **callback_kwargs)
  File "/home/wercules/medreport/mrApp/views.py", line 76, in pesquisar_atendimento
    atendimento = request.POST['paciente_id']
  File "/home/wercules/.local/share/virtualenvs/medreport-3oUkA-aL/lib/python3.6/site-packages/django/utils/datastructures.py", line 80, in __getitem__
    raise MultiValueDictKeyError(key)
django.utils.datastructures.MultiValueDictKeyError: 'paciente_id'
[02/Jun/2019 22:16:18] "GET /mr/pesquisar_atendimento?paciente_id=1 HTTP/1.1" 500 75879
[02/Jun/2019 22:16:24] "POST /mr/procurar_paciente HTTP/1.1" 200 2050
Not Found: /resources/demos/style.css
[02/Jun/2019 22:16:25] "GET /resources/demos/style.css HTTP/1.1" 404 2241
Forbidden (CSRF token missing or incorrect.): /mr/pesquisar_atendimento
[02/Jun/2019 22:16:27] "POST /mr/pesquisar_atendimento HTTP/1.1" 403 2513
Forbidden (CSRF token missing or incorrect.): /mr/pesquisar_atendimento
[02/Jun/2019 22:16:57] "POST /mr/pesquisar_atendimento HTTP/1.1" 403 2513
[02/Jun/2019 22:17:01] "POST /mr/procurar_paciente HTTP/1.1" 200 2171
Not Found: /resources/demos/style.css
[02/Jun/2019 22:17:02] "GET /resources/demos/style.css HTTP/1.1" 404 2241
[02/Jun/2019 22:17:03] "POST /mr/pesquisar_atendimento HTTP/1.1" 200 1
/home/wercules/medreport/mrApp/views.py changed, reloading.
Performing system checks...

System check identified no issues (0 silenced).
June 02, 2019 - 22:12:04
Django version 2.2.1, using settings 'mrProject.settings'
Starting development server at http://cardiobemestar.com.br:8000/
Quit the server with CONTROL-C.
Watching for file changes with StatReloader
/home/wercules/medreport/mrApp/views.py changed, reloading.
Performing system checks...

System check identified no issues (0 silenced).
June 02, 2019 - 22:18:45
Django version 2.2.1, using settings 'mrProject.settings'
Starting development server at http://cardiobemestar.com.br:8000/
Quit the server with CONTROL-C.
Watching for file changes with StatReloader
/home/wercules/medreport/mrApp/views.py changed, reloading.
Performing system checks...

System check identified no issues (0 silenced).
June 02, 2019 - 22:18:51
Django version 2.2.1, using settings 'mrProject.settings'
Starting development server at http://cardiobemestar.com.br:8000/
Quit the server with CONTROL-C.
Watching for file changes with StatReloader
/home/wercules/medreport/mrApp/views.py changed, reloading.
Performing system checks...

System check identified no issues (0 silenced).
June 02, 2019 - 22:19:00
Django version 2.2.1, using settings 'mrProject.settings'
Starting development server at http://cardiobemestar.com.br:8000/
Quit the server with CONTROL-C.
Watching for file changes with StatReloader
[02/Jun/2019 22:19:41] "POST /mr/procurar_paciente HTTP/1.1" 200 2171
Not Found: /resources/demos/style.css
[02/Jun/2019 22:19:41] "GET /resources/demos/style.css HTTP/1.1" 404 2241
Internal Server Error: /mr/pesquisar_atendimento
Traceback (most recent call last):
  File "/home/wercules/.local/share/virtualenvs/medreport-3oUkA-aL/lib/python3.6/site-packages/django/core/handlers/exception.py", line 34, in inner
    response = get_response(request)
  File "/home/wercules/.local/share/virtualenvs/medreport-3oUkA-aL/lib/python3.6/site-packages/django/core/handlers/base.py", line 115, in _get_response
    response = self.process_exception_by_middleware(e, request)
  File "/home/wercules/.local/share/virtualenvs/medreport-3oUkA-aL/lib/python3.6/site-packages/django/core/handlers/base.py", line 113, in _get_response
    response = wrapped_callback(request, *callback_args, **callback_kwargs)
  File "/home/wercules/medreport/mrApp/views.py", line 77, in pesquisar_atendimento
    return HttpResponse(atendimento.data_atendimento)
AttributeError: 'QuerySet' object has no attribute 'data_atendimento'
[02/Jun/2019 22:19:43] "POST /mr/pesquisar_atendimento HTTP/1.1" 500 67834
/home/wercules/medreport/mrApp/views.py changed, reloading.
Performing system checks...

System check identified no issues (0 silenced).
June 02, 2019 - 22:19:29
Django version 2.2.1, using settings 'mrProject.settings'
Starting development server at http://cardiobemestar.com.br:8000/
Quit the server with CONTROL-C.
Watching for file changes with StatReloader
/home/wercules/medreport/mrApp/views.py changed, reloading.
Performing system checks...

System check identified no issues (0 silenced).
June 02, 2019 - 22:20:12
Django version 2.2.1, using settings 'mrProject.settings'
Starting development server at http://cardiobemestar.com.br:8000/
Quit the server with CONTROL-C.
Watching for file changes with StatReloader
[02/Jun/2019 22:20:25] "POST /mr/procurar_paciente HTTP/1.1" 200 2171
Not Found: /resources/demos/style.css
[02/Jun/2019 22:20:26] "GET /resources/demos/style.css HTTP/1.1" 404 2241
[02/Jun/2019 22:20:28] "POST /mr/pesquisar_atendimento HTTP/1.1" 200 0
/home/wercules/medreport/mrApp/views.py changed, reloading.
Performing system checks...

System check identified no issues (0 silenced).
June 02, 2019 - 22:20:17
Django version 2.2.1, using settings 'mrProject.settings'
Starting development server at http://cardiobemestar.com.br:8000/
Quit the server with CONTROL-C.
Watching for file changes with StatReloader
[02/Jun/2019 22:24:48] "GET /mr/search?term=Ta HTTP/1.1" 200 36
[02/Jun/2019 22:24:48] "GET /mr/search?term=Tadeu HTTP/1.1" 200 36
[02/Jun/2019 22:24:51] "POST /mr/procurar_paciente HTTP/1.1" 200 2169
Not Found: /resources/demos/style.css
[02/Jun/2019 22:24:52] "GET /resources/demos/style.css HTTP/1.1" 404 2241
Not Found: /favicon.ico
[02/Jun/2019 22:24:52] "GET /favicon.ico HTTP/1.1" 404 2199
[02/Jun/2019 22:24:54] "POST /mr/pesquisar_atendimento HTTP/1.1" 200 316
[03/Jun/2019 12:45:41] code 400, message Bad HTTP/0.9 request type ('\x03\x00\x00/*à\x00\x00\x00\x00\x00Cookie:')
[03/Jun/2019 12:45:41] "  /*à     Cookie: mstshash=Administr" 400 -
Not Found: /
[03/Jun/2019 18:29:36] "GET / HTTP/1.1" 404 2143
Invalid HTTP_HOST header: 'andreagaspar.com.br'. You may need to add 'andreagaspar.com.br' to ALLOWED_HOSTS.
Bad Request: /
[03/Jun/2019 20:14:47] "GET / HTTP/1.1" 400 63587
Invalid HTTP_HOST header: 'www.rodrigocordovil.com.br'. You may need to add 'www.rodrigocordovil.com.br' to ALLOWED_HOSTS.
Bad Request: /
[03/Jun/2019 22:26:01] "GET / HTTP/1.1" 400 63693
Invalid HTTP_HOST header: '185.135.8.139:8000'. You may need to add '185.135.8.139' to ALLOWED_HOSTS.
Bad Request: /
[04/Jun/2019 01:58:52] "GET / HTTP/1.1" 400 63630
Invalid HTTP_HOST header: '185.135.8.139:8000'. You may need to add '185.135.8.139' to ALLOWED_HOSTS.
Bad Request: /
[04/Jun/2019 02:47:57] "HEAD / HTTP/1.1" 400 64124
[04/Jun/2019 03:38:27] code 400, message Bad HTTP/0.9 request type ('\x03\x00\x00/*à\x00\x00\x00\x00\x00Cookie:')
[04/Jun/2019 03:38:27] "  /*à     Cookie: mstshash=Administr" 400 -
Invalid HTTP_HOST header: 'rodrigocordovil.com.br'. You may need to add 'rodrigocordovil.com.br' to ALLOWED_HOSTS.
Bad Request: /
[04/Jun/2019 04:32:43] "GET / HTTP/1.1" 400 63632
Invalid HTTP_HOST header: 'drantoniobacelar.com.br'. You may need to add 'drantoniobacelar.com.br' to ALLOWED_HOSTS.
Bad Request: /
[04/Jun/2019 08:10:06] "GET / HTTP/1.1" 400 63648
Invalid HTTP_HOST header: 'www.drantoniobacelar.com.br'. You may need to add 'www.drantoniobacelar.com.br' to ALLOWED_HOSTS.
Bad Request: /
[04/Jun/2019 08:26:32] "GET / HTTP/1.1" 400 63707
Invalid HTTP_HOST header: '185.135.8.139:8000'. You may need to add '185.135.8.139' to ALLOWED_HOSTS.
Bad Request: /
[04/Jun/2019 12:27:18] "GET / HTTP/1.1" 400 63723
Traceback (most recent call last):
  File "/usr/lib64/python3.6/wsgiref/handlers.py", line 138, in run
    self.finish_response()
  File "/usr/lib64/python3.6/wsgiref/handlers.py", line 180, in finish_response
    self.write(data)
  File "/usr/lib64/python3.6/wsgiref/handlers.py", line 279, in write
    self._write(data)
  File "/usr/lib64/python3.6/wsgiref/handlers.py", line 453, in _write
    result = self.stdout.write(data)
  File "/usr/lib64/python3.6/socketserver.py", line 803, in write
    self._sock.sendall(b)
ConnectionResetError: [Errno 104] Connection reset by peer
[04/Jun/2019 12:27:18] "GET / HTTP/1.1" 500 59
----------------------------------------
Exception happened during processing of request from ('139.162.79.87', 50660)
Traceback (most recent call last):
  File "/usr/lib64/python3.6/wsgiref/handlers.py", line 138, in run
    self.finish_response()
  File "/usr/lib64/python3.6/wsgiref/handlers.py", line 180, in finish_response
    self.write(data)
  File "/usr/lib64/python3.6/wsgiref/handlers.py", line 279, in write
    self._write(data)
  File "/usr/lib64/python3.6/wsgiref/handlers.py", line 453, in _write
    result = self.stdout.write(data)
  File "/usr/lib64/python3.6/socketserver.py", line 803, in write
    self._sock.sendall(b)
ConnectionResetError: [Errno 104] Connection reset by peer

During handling of the above exception, another exception occurred:

Traceback (most recent call last):
  File "/usr/lib64/python3.6/wsgiref/handlers.py", line 141, in run
    self.handle_error()
  File "/home/wercules/.local/share/virtualenvs/medreport-3oUkA-aL/lib/python3.6/site-packages/django/core/servers/basehttp.py", line 116, in handle_error
    super().handle_error()
  File "/usr/lib64/python3.6/wsgiref/handlers.py", line 368, in handle_error
    self.finish_response()
  File "/usr/lib64/python3.6/wsgiref/handlers.py", line 180, in finish_response
    self.write(data)
  File "/usr/lib64/python3.6/wsgiref/handlers.py", line 274, in write
    self.send_headers()
  File "/usr/lib64/python3.6/wsgiref/handlers.py", line 331, in send_headers
    if not self.origin_server or self.client_is_modern():
  File "/usr/lib64/python3.6/wsgiref/handlers.py", line 344, in client_is_modern
    return self.environ['SERVER_PROTOCOL'].upper() != 'HTTP/0.9'
TypeError: 'NoneType' object is not subscriptable

During handling of the above exception, another exception occurred:

Traceback (most recent call last):
  File "/usr/lib64/python3.6/socketserver.py", line 654, in process_request_thread
    self.finish_request(request, client_address)
  File "/usr/lib64/python3.6/socketserver.py", line 364, in finish_request
    self.RequestHandlerClass(request, client_address, self)
  File "/usr/lib64/python3.6/socketserver.py", line 724, in __init__
    self.handle()
  File "/home/wercules/.local/share/virtualenvs/medreport-3oUkA-aL/lib/python3.6/site-packages/django/core/servers/basehttp.py", line 169, in handle
    self.handle_one_request()
  File "/home/wercules/.local/share/virtualenvs/medreport-3oUkA-aL/lib/python3.6/site-packages/django/core/servers/basehttp.py", line 194, in handle_one_request
    handler.run(self.server.get_app())
  File "/usr/lib64/python3.6/wsgiref/handlers.py", line 144, in run
    self.close()
  File "/home/wercules/.local/share/virtualenvs/medreport-3oUkA-aL/lib/python3.6/site-packages/django/core/servers/basehttp.py", line 111, in close
    super().close()
  File "/usr/lib64/python3.6/wsgiref/simple_server.py", line 35, in close
    self.status.split(' ',1)[0], self.bytes_sent
AttributeError: 'NoneType' object has no attribute 'split'
----------------------------------------
Invalid HTTP_HOST header: '185.135.8.139:8000'. You may need to add '185.135.8.139' to ALLOWED_HOSTS.
Bad Request: /
[04/Jun/2019 15:42:31] "GET / HTTP/1.1" 400 63630
----------------------------------------
Exception happened during processing of request from ('91.206.15.132', 60000)
Traceback (most recent call last):
  File "/usr/lib64/python3.6/socketserver.py", line 654, in process_request_thread
    self.finish_request(request, client_address)
  File "/usr/lib64/python3.6/socketserver.py", line 364, in finish_request
    self.RequestHandlerClass(request, client_address, self)
  File "/usr/lib64/python3.6/socketserver.py", line 724, in __init__
    self.handle()
  File "/home/wercules/.local/share/virtualenvs/medreport-3oUkA-aL/lib/python3.6/site-packages/django/core/servers/basehttp.py", line 169, in handle
    self.handle_one_request()
  File "/home/wercules/.local/share/virtualenvs/medreport-3oUkA-aL/lib/python3.6/site-packages/django/core/servers/basehttp.py", line 179, in handle_one_request
    self.raw_requestline = self.rfile.readline(65537)
  File "/usr/lib64/python3.6/socket.py", line 586, in readinto
    return self._sock.recv_into(b)
ConnectionResetError: [Errno 104] Connection reset by peer
----------------------------------------
Invalid HTTP_HOST header: 'clinicarharmonia.com.br'. You may need to add 'clinicarharmonia.com.br' to ALLOWED_HOSTS.
Bad Request: /
[04/Jun/2019 19:43:20] "GET / HTTP/1.1" 400 63647
Invalid HTTP_HOST header: 'www.clinicarharmonia.com.br'. You may need to add 'www.clinicarharmonia.com.br' to ALLOWED_HOSTS.
Bad Request: /
[05/Jun/2019 03:21:20] "GET / HTTP/1.1" 400 63707
Invalid HTTP_HOST header: 'www.andreagaspar.com.br'. You may need to add 'www.andreagaspar.com.br' to ALLOWED_HOSTS.
Bad Request: /
[05/Jun/2019 04:59:37] "GET / HTTP/1.1" 400 63647
Invalid HTTP_HOST header: 'www.crharmonia.com.br'. You may need to add 'www.crharmonia.com.br' to ALLOWED_HOSTS.
Bad Request: /
[05/Jun/2019 13:51:52] "GET / HTTP/1.1" 400 63618
Invalid HTTP_HOST header: 'check.best-proxies.ru'. You may need to add 'check.best-proxies.ru' to ALLOWED_HOSTS.
Bad Request: /http:/check.best-proxies.ru/azenv.php
[06/Jun/2019 10:16:49] "POST http://check.best-proxies.ru/azenv.php?auth=155981620907194&a=PC&i=3112634507&p=8000 HTTP/1.1" 400 66104
Invalid HTTP_HOST header: 'check.best-proxies.ru:80'. You may need to add 'check.best-proxies.ru' to ALLOWED_HOSTS.
Bad Request: /check.best-proxies.ru:80
[06/Jun/2019 10:16:54] "CONNECT check.best-proxies.ru:80 HTTP/1.1" 400 63718
[06/Jun/2019 10:17:04] code 400, message Bad request syntax ('\x04\x01\x00P\x05²VL0\x00')
[06/Jun/2019 10:17:04] " P²VL0 " 400 -
[2019-06-06 10:17:04,871] - Broken pipe from ('109.234.153.133', 54968)

[06/Jun/2019 10:17:10] code 400, message Bad request syntax ('\x05\x01\x00')
[06/Jun/2019 10:17:10] " " 400 -
[2019-06-06 10:17:10,108] - Broken pipe from ('109.234.153.130', 42823)

[06/Jun/2019 14:12:56] code 400, message Bad HTTP/0.9 request type ('\x03\x00\x00/*à\x00\x00\x00\x00\x00Cookie:')
[06/Jun/2019 14:12:56] "  /*à     Cookie: mstshash=Administr" 400 -
Invalid HTTP_HOST header: '185.135.8.139:8000'. You may need to add '185.135.8.139' to ALLOWED_HOSTS.
Bad Request: /
[06/Jun/2019 20:34:55] "GET / HTTP/1.1" 400 63723
Invalid HTTP_HOST header: 'www.cardiobemestar.com.br:8000'. You may need to add 'www.cardiobemestar.com.br' to ALLOWED_HOSTS.
Bad Request: /mr
[06/Jun/2019 21:01:07] "GET /mr HTTP/1.1" 400 65648
Invalid HTTP_HOST header: 'www.cardiobemestar.com.br:8000'. You may need to add 'www.cardiobemestar.com.br' to ALLOWED_HOSTS.
Bad Request: /favicon.ico
[06/Jun/2019 21:01:07] "GET /favicon.ico HTTP/1.1" 400 65559
[06/Jun/2019 21:01:18] "GET /mr/ HTTP/1.1" 200 2439
Not Found: /resources/demos/style.css
[06/Jun/2019 21:01:18] "GET /resources/demos/style.css HTTP/1.1" 404 2241
[06/Jun/2019 21:01:18] "GET /static/css/style.css HTTP/1.1" 200 532
[06/Jun/2019 21:01:18] "GET /static/js/main.js HTTP/1.1" 200 123
Not Found: /favicon.ico
[06/Jun/2019 21:01:19] "GET /favicon.ico HTTP/1.1" 404 2199
[06/Jun/2019 21:01:22] "GET /mr/search?term=wer HTTP/1.1" 200 2
[06/Jun/2019 21:01:26] "GET /mr/search?term=P HTTP/1.1" 200 2
[06/Jun/2019 21:01:28] "GET /mr/search?term=F HTTP/1.1" 200 2
[06/Jun/2019 21:01:35] "GET /mr/adicionar_paciente HTTP/1.1" 200 3474
Not Found: /resources/demos/style.css
[06/Jun/2019 21:01:35] "GET /resources/demos/style.css HTTP/1.1" 404 2241
[06/Jun/2019 21:01:35] "GET /static/css/style.css HTTP/1.1" 200 532
Not Found: /favicon.ico
[06/Jun/2019 21:01:36] "GET /favicon.ico HTTP/1.1" 404 2199
Not Found: /resources/demos/style.css
[06/Jun/2019 21:01:38] "GET /resources/demos/style.css HTTP/1.1" 404 2241
[06/Jun/2019 21:02:29] "GET /mr/search?term=Ta HTTP/1.1" 200 36
[06/Jun/2019 21:02:33] "POST /mr/procurar_paciente HTTP/1.1" 200 2169
Not Found: /resources/demos/style.css
[06/Jun/2019 21:02:33] "GET /resources/demos/style.css HTTP/1.1" 404 2241
Not Found: /favicon.ico
[06/Jun/2019 21:02:34] "GET /favicon.ico HTTP/1.1" 404 2199
[06/Jun/2019 21:02:36] "POST /mr/pesquisar_atendimento HTTP/1.1" 200 316
/home/wercules/medreport/mrApp/views.py changed, reloading.
Performing system checks...

System check identified no issues (0 silenced).
June 02, 2019 - 22:24:42
Django version 2.2.1, using settings 'mrProject.settings'
Starting development server at http://cardiobemestar.com.br:8000/
Quit the server with CONTROL-C.
Watching for file changes with StatReloader
[06/Jun/2019 21:27:40] "POST /mr/procurar_paciente HTTP/1.1" 200 2169
Not Found: /resources/demos/style.css
[06/Jun/2019 21:27:41] "GET /resources/demos/style.css HTTP/1.1" 404 2241
Not Found: /favicon.ico
[06/Jun/2019 21:27:41] "GET /favicon.ico HTTP/1.1" 404 2199
[06/Jun/2019 21:27:44] "POST /mr/pesquisar_atendimento HTTP/1.1" 200 2092
Not Found: /resources/demos/style.css
[06/Jun/2019 21:27:45] "GET /resources/demos/style.css HTTP/1.1" 404 2241
Not Found: /favicon.ico
[06/Jun/2019 21:27:45] "GET /favicon.ico HTTP/1.1" 404 2199
/home/wercules/medreport/mrApp/views.py changed, reloading.
Performing system checks...

System check identified no issues (0 silenced).
June 06, 2019 - 21:19:49
Django version 2.2.1, using settings 'mrProject.settings'
Starting development server at http://cardiobemestar.com.br:8000/
Quit the server with CONTROL-C.
Watching for file changes with StatReloader
Internal Server Error: /mr/pesquisar_atendimento
Traceback (most recent call last):
  File "/home/wercules/.local/share/virtualenvs/medreport-3oUkA-aL/lib/python3.6/site-packages/django/core/handlers/exception.py", line 34, in inner
    response = get_response(request)
  File "/home/wercules/.local/share/virtualenvs/medreport-3oUkA-aL/lib/python3.6/site-packages/django/core/handlers/base.py", line 115, in _get_response
    response = self.process_exception_by_middleware(e, request)
  File "/home/wercules/.local/share/virtualenvs/medreport-3oUkA-aL/lib/python3.6/site-packages/django/core/handlers/base.py", line 113, in _get_response
    response = wrapped_callback(request, *callback_args, **callback_kwargs)
  File "/home/wercules/medreport/mrApp/views.py", line 85, in pesquisar_atendimento
    contexts.append(context)
NameError: name 'contexts' is not defined
[07/Jun/2019 00:15:33] "POST /mr/pesquisar_atendimento HTTP/1.1" 500 68378
Not Found: /favicon.ico
[07/Jun/2019 00:15:33] "GET /favicon.ico HTTP/1.1" 404 2199
/home/wercules/medreport/mrApp/views.py changed, reloading.
Performing system checks...

System check identified no issues (0 silenced).
June 07, 2019 - 00:15:26
Django version 2.2.1, using settings 'mrProject.settings'
Starting development server at http://cardiobemestar.com.br:8000/
Quit the server with CONTROL-C.
Watching for file changes with StatReloader
[07/Jun/2019 00:15:55] "POST /mr/pesquisar_atendimento HTTP/1.1" 200 2498
Not Found: /resources/demos/style.css
[07/Jun/2019 00:15:55] "GET /resources/demos/style.css HTTP/1.1" 404 2241
Not Found: /favicon.ico
[07/Jun/2019 00:15:56] "GET /favicon.ico HTTP/1.1" 404 2199
/home/wercules/medreport/mrApp/views.py changed, reloading.
Performing system checks...

System check identified no issues (0 silenced).
June 07, 2019 - 00:15:50
Django version 2.2.1, using settings 'mrProject.settings'
Starting development server at http://cardiobemestar.com.br:8000/
Quit the server with CONTROL-C.
Watching for file changes with StatReloader
Exception in thread django-main-thread:
Traceback (most recent call last):
  File "/usr/lib64/python3.6/threading.py", line 916, in _bootstrap_inner
    self.run()
  File "/usr/lib64/python3.6/threading.py", line 864, in run
    self._target(*self._args, **self._kwargs)
  File "/home/wercules/.local/share/virtualenvs/medreport-3oUkA-aL/lib/python3.6/site-packages/django/utils/autoreload.py", line 54, in wrapper
    fn(*args, **kwargs)
  File "/home/wercules/.local/share/virtualenvs/medreport-3oUkA-aL/lib/python3.6/site-packages/django/core/management/commands/runserver.py", line 117, in inner_run
    self.check(display_num_errors=True)
  File "/home/wercules/.local/share/virtualenvs/medreport-3oUkA-aL/lib/python3.6/site-packages/django/core/management/base.py", line 390, in check
    include_deployment_checks=include_deployment_checks,
  File "/home/wercules/.local/share/virtualenvs/medreport-3oUkA-aL/lib/python3.6/site-packages/django/core/management/base.py", line 377, in _run_checks
    return checks.run_checks(**kwargs)
  File "/home/wercules/.local/share/virtualenvs/medreport-3oUkA-aL/lib/python3.6/site-packages/django/core/checks/registry.py", line 72, in run_checks
    new_errors = check(app_configs=app_configs)
  File "/home/wercules/.local/share/virtualenvs/medreport-3oUkA-aL/lib/python3.6/site-packages/django/core/checks/urls.py", line 13, in check_url_config
    return check_resolver(resolver)
  File "/home/wercules/.local/share/virtualenvs/medreport-3oUkA-aL/lib/python3.6/site-packages/django/core/checks/urls.py", line 23, in check_resolver
    return check_method()
  File "/home/wercules/.local/share/virtualenvs/medreport-3oUkA-aL/lib/python3.6/site-packages/django/urls/resolvers.py", line 398, in check
    for pattern in self.url_patterns:
  File "/home/wercules/.local/share/virtualenvs/medreport-3oUkA-aL/lib/python3.6/site-packages/django/utils/functional.py", line 80, in __get__
    res = instance.__dict__[self.name] = self.func(instance)
  File "/home/wercules/.local/share/virtualenvs/medreport-3oUkA-aL/lib/python3.6/site-packages/django/urls/resolvers.py", line 579, in url_patterns
    patterns = getattr(self.urlconf_module, "urlpatterns", self.urlconf_module)
  File "/home/wercules/.local/share/virtualenvs/medreport-3oUkA-aL/lib/python3.6/site-packages/django/utils/functional.py", line 80, in __get__
    res = instance.__dict__[self.name] = self.func(instance)
  File "/home/wercules/.local/share/virtualenvs/medreport-3oUkA-aL/lib/python3.6/site-packages/django/urls/resolvers.py", line 572, in urlconf_module
    return import_module(self.urlconf_name)
  File "/home/wercules/.local/share/virtualenvs/medreport-3oUkA-aL/lib64/python3.6/importlib/__init__.py", line 126, in import_module
    return _bootstrap._gcd_import(name[level:], package, level)
  File "<frozen importlib._bootstrap>", line 994, in _gcd_import
  File "<frozen importlib._bootstrap>", line 971, in _find_and_load
  File "<frozen importlib._bootstrap>", line 955, in _find_and_load_unlocked
  File "<frozen importlib._bootstrap>", line 665, in _load_unlocked
  File "<frozen importlib._bootstrap_external>", line 678, in exec_module
  File "<frozen importlib._bootstrap>", line 219, in _call_with_frames_removed
  File "/home/wercules/medreport/mrProject/urls.py", line 20, in <module>
    path('mr/', include('mrApp.urls')),
  File "/home/wercules/.local/share/virtualenvs/medreport-3oUkA-aL/lib/python3.6/site-packages/django/urls/conf.py", line 34, in include
    urlconf_module = import_module(urlconf_module)
  File "/home/wercules/.local/share/virtualenvs/medreport-3oUkA-aL/lib64/python3.6/importlib/__init__.py", line 126, in import_module
    return _bootstrap._gcd_import(name[level:], package, level)
  File "<frozen importlib._bootstrap>", line 994, in _gcd_import
  File "<frozen importlib._bootstrap>", line 971, in _find_and_load
  File "<frozen importlib._bootstrap>", line 955, in _find_and_load_unlocked
  File "<frozen importlib._bootstrap>", line 665, in _load_unlocked
  File "<frozen importlib._bootstrap_external>", line 678, in exec_module
  File "<frozen importlib._bootstrap>", line 219, in _call_with_frames_removed
  File "/home/wercules/medreport/mrApp/urls.py", line 14, in <module>
    path('pesquisar_atendimento', views.pesquisar_atendimento, name = 'pesquisar_atendimento'),
AttributeError: module 'mrApp.views' has no attribute 'pesquisar_atendimento'

/home/wercules/medreport/mrApp/views.py changed, reloading.
Performing system checks...

Watching for file changes with StatReloader
Exception in thread django-main-thread:
Traceback (most recent call last):
  File "/usr/lib64/python3.6/threading.py", line 916, in _bootstrap_inner
    self.run()
  File "/usr/lib64/python3.6/threading.py", line 864, in run
    self._target(*self._args, **self._kwargs)
  File "/home/wercules/.local/share/virtualenvs/medreport-3oUkA-aL/lib/python3.6/site-packages/django/utils/autoreload.py", line 54, in wrapper
    fn(*args, **kwargs)
  File "/home/wercules/.local/share/virtualenvs/medreport-3oUkA-aL/lib/python3.6/site-packages/django/core/management/commands/runserver.py", line 117, in inner_run
    self.check(display_num_errors=True)
  File "/home/wercules/.local/share/virtualenvs/medreport-3oUkA-aL/lib/python3.6/site-packages/django/core/management/base.py", line 390, in check
    include_deployment_checks=include_deployment_checks,
  File "/home/wercules/.local/share/virtualenvs/medreport-3oUkA-aL/lib/python3.6/site-packages/django/core/management/base.py", line 377, in _run_checks
    return checks.run_checks(**kwargs)
  File "/home/wercules/.local/share/virtualenvs/medreport-3oUkA-aL/lib/python3.6/site-packages/django/core/checks/registry.py", line 72, in run_checks
    new_errors = check(app_configs=app_configs)
  File "/home/wercules/.local/share/virtualenvs/medreport-3oUkA-aL/lib/python3.6/site-packages/django/core/checks/urls.py", line 13, in check_url_config
    return check_resolver(resolver)
  File "/home/wercules/.local/share/virtualenvs/medreport-3oUkA-aL/lib/python3.6/site-packages/django/core/checks/urls.py", line 23, in check_resolver
    return check_method()
  File "/home/wercules/.local/share/virtualenvs/medreport-3oUkA-aL/lib/python3.6/site-packages/django/urls/resolvers.py", line 398, in check
    for pattern in self.url_patterns:
  File "/home/wercules/.local/share/virtualenvs/medreport-3oUkA-aL/lib/python3.6/site-packages/django/utils/functional.py", line 80, in __get__
    res = instance.__dict__[self.name] = self.func(instance)
  File "/home/wercules/.local/share/virtualenvs/medreport-3oUkA-aL/lib/python3.6/site-packages/django/urls/resolvers.py", line 579, in url_patterns
    patterns = getattr(self.urlconf_module, "urlpatterns", self.urlconf_module)
  File "/home/wercules/.local/share/virtualenvs/medreport-3oUkA-aL/lib/python3.6/site-packages/django/utils/functional.py", line 80, in __get__
    res = instance.__dict__[self.name] = self.func(instance)
  File "/home/wercules/.local/share/virtualenvs/medreport-3oUkA-aL/lib/python3.6/site-packages/django/urls/resolvers.py", line 572, in urlconf_module
    return import_module(self.urlconf_name)
  File "/home/wercules/.local/share/virtualenvs/medreport-3oUkA-aL/lib64/python3.6/importlib/__init__.py", line 126, in import_module
    return _bootstrap._gcd_import(name[level:], package, level)
  File "<frozen importlib._bootstrap>", line 994, in _gcd_import
  File "<frozen importlib._bootstrap>", line 971, in _find_and_load
  File "<frozen importlib._bootstrap>", line 955, in _find_and_load_unlocked
  File "<frozen importlib._bootstrap>", line 665, in _load_unlocked
  File "<frozen importlib._bootstrap_external>", line 678, in exec_module
  File "<frozen importlib._bootstrap>", line 219, in _call_with_frames_removed
  File "/home/wercules/medreport/mrProject/urls.py", line 20, in <module>
    path('mr/', include('mrApp.urls')),
  File "/home/wercules/.local/share/virtualenvs/medreport-3oUkA-aL/lib/python3.6/site-packages/django/urls/conf.py", line 34, in include
    urlconf_module = import_module(urlconf_module)
  File "/home/wercules/.local/share/virtualenvs/medreport-3oUkA-aL/lib64/python3.6/importlib/__init__.py", line 126, in import_module
    return _bootstrap._gcd_import(name[level:], package, level)
  File "<frozen importlib._bootstrap>", line 994, in _gcd_import
  File "<frozen importlib._bootstrap>", line 971, in _find_and_load
  File "<frozen importlib._bootstrap>", line 955, in _find_and_load_unlocked
  File "<frozen importlib._bootstrap>", line 665, in _load_unlocked
  File "<frozen importlib._bootstrap_external>", line 678, in exec_module
  File "<frozen importlib._bootstrap>", line 219, in _call_with_frames_removed
  File "/home/wercules/medreport/mrApp/urls.py", line 14, in <module>
    path('pesquisar_atendimento', views.pesquisar_atendimento, name = 'pesquisar_atendimento'),
AttributeError: module 'mrApp.views' has no attribute 'pesquisar_atendimento'

/home/wercules/medreport/mrApp/views.py changed, reloading.
Performing system checks...

Watching for file changes with StatReloader
Exception in thread django-main-thread:
Traceback (most recent call last):
  File "/usr/lib64/python3.6/threading.py", line 916, in _bootstrap_inner
    self.run()
  File "/usr/lib64/python3.6/threading.py", line 864, in run
    self._target(*self._args, **self._kwargs)
  File "/home/wercules/.local/share/virtualenvs/medreport-3oUkA-aL/lib/python3.6/site-packages/django/utils/autoreload.py", line 54, in wrapper
    fn(*args, **kwargs)
  File "/home/wercules/.local/share/virtualenvs/medreport-3oUkA-aL/lib/python3.6/site-packages/django/core/management/commands/runserver.py", line 117, in inner_run
    self.check(display_num_errors=True)
  File "/home/wercules/.local/share/virtualenvs/medreport-3oUkA-aL/lib/python3.6/site-packages/django/core/management/base.py", line 390, in check
    include_deployment_checks=include_deployment_checks,
  File "/home/wercules/.local/share/virtualenvs/medreport-3oUkA-aL/lib/python3.6/site-packages/django/core/management/base.py", line 377, in _run_checks
    return checks.run_checks(**kwargs)
  File "/home/wercules/.local/share/virtualenvs/medreport-3oUkA-aL/lib/python3.6/site-packages/django/core/checks/registry.py", line 72, in run_checks
    new_errors = check(app_configs=app_configs)
  File "/home/wercules/.local/share/virtualenvs/medreport-3oUkA-aL/lib/python3.6/site-packages/django/core/checks/urls.py", line 13, in check_url_config
    return check_resolver(resolver)
  File "/home/wercules/.local/share/virtualenvs/medreport-3oUkA-aL/lib/python3.6/site-packages/django/core/checks/urls.py", line 23, in check_resolver
    return check_method()
  File "/home/wercules/.local/share/virtualenvs/medreport-3oUkA-aL/lib/python3.6/site-packages/django/urls/resolvers.py", line 398, in check
    for pattern in self.url_patterns:
  File "/home/wercules/.local/share/virtualenvs/medreport-3oUkA-aL/lib/python3.6/site-packages/django/utils/functional.py", line 80, in __get__
    res = instance.__dict__[self.name] = self.func(instance)
  File "/home/wercules/.local/share/virtualenvs/medreport-3oUkA-aL/lib/python3.6/site-packages/django/urls/resolvers.py", line 579, in url_patterns
    patterns = getattr(self.urlconf_module, "urlpatterns", self.urlconf_module)
  File "/home/wercules/.local/share/virtualenvs/medreport-3oUkA-aL/lib/python3.6/site-packages/django/utils/functional.py", line 80, in __get__
    res = instance.__dict__[self.name] = self.func(instance)
  File "/home/wercules/.local/share/virtualenvs/medreport-3oUkA-aL/lib/python3.6/site-packages/django/urls/resolvers.py", line 572, in urlconf_module
    return import_module(self.urlconf_name)
  File "/home/wercules/.local/share/virtualenvs/medreport-3oUkA-aL/lib64/python3.6/importlib/__init__.py", line 126, in import_module
    return _bootstrap._gcd_import(name[level:], package, level)
  File "<frozen importlib._bootstrap>", line 994, in _gcd_import
  File "<frozen importlib._bootstrap>", line 971, in _find_and_load
  File "<frozen importlib._bootstrap>", line 955, in _find_and_load_unlocked
  File "<frozen importlib._bootstrap>", line 665, in _load_unlocked
  File "<frozen importlib._bootstrap_external>", line 678, in exec_module
  File "<frozen importlib._bootstrap>", line 219, in _call_with_frames_removed
  File "/home/wercules/medreport/mrProject/urls.py", line 20, in <module>
    path('mr/', include('mrApp.urls')),
  File "/home/wercules/.local/share/virtualenvs/medreport-3oUkA-aL/lib/python3.6/site-packages/django/urls/conf.py", line 34, in include
    urlconf_module = import_module(urlconf_module)
  File "/home/wercules/.local/share/virtualenvs/medreport-3oUkA-aL/lib64/python3.6/importlib/__init__.py", line 126, in import_module
    return _bootstrap._gcd_import(name[level:], package, level)
  File "<frozen importlib._bootstrap>", line 994, in _gcd_import
  File "<frozen importlib._bootstrap>", line 971, in _find_and_load
  File "<frozen importlib._bootstrap>", line 955, in _find_and_load_unlocked
  File "<frozen importlib._bootstrap>", line 665, in _load_unlocked
  File "<frozen importlib._bootstrap_external>", line 678, in exec_module
  File "<frozen importlib._bootstrap>", line 219, in _call_with_frames_removed
  File "/home/wercules/medreport/mrApp/urls.py", line 14, in <module>
    path('pesquisar_atendimento', views.pesquisar_atendimento, name = 'pesquisar_atendimento'),
AttributeError: module 'mrApp.views' has no attribute 'pesquisar_atendimento'

/home/wercules/medreport/mrApp/views.py changed, reloading.
Performing system checks...

Watching for file changes with StatReloader
Exception in thread django-main-thread:
Traceback (most recent call last):
  File "/usr/lib64/python3.6/threading.py", line 916, in _bootstrap_inner
    self.run()
  File "/usr/lib64/python3.6/threading.py", line 864, in run
    self._target(*self._args, **self._kwargs)
  File "/home/wercules/.local/share/virtualenvs/medreport-3oUkA-aL/lib/python3.6/site-packages/django/utils/autoreload.py", line 54, in wrapper
    fn(*args, **kwargs)
  File "/home/wercules/.local/share/virtualenvs/medreport-3oUkA-aL/lib/python3.6/site-packages/django/core/management/commands/runserver.py", line 117, in inner_run
    self.check(display_num_errors=True)
  File "/home/wercules/.local/share/virtualenvs/medreport-3oUkA-aL/lib/python3.6/site-packages/django/core/management/base.py", line 390, in check
    include_deployment_checks=include_deployment_checks,
  File "/home/wercules/.local/share/virtualenvs/medreport-3oUkA-aL/lib/python3.6/site-packages/django/core/management/base.py", line 377, in _run_checks
    return checks.run_checks(**kwargs)
  File "/home/wercules/.local/share/virtualenvs/medreport-3oUkA-aL/lib/python3.6/site-packages/django/core/checks/registry.py", line 72, in run_checks
    new_errors = check(app_configs=app_configs)
  File "/home/wercules/.local/share/virtualenvs/medreport-3oUkA-aL/lib/python3.6/site-packages/django/core/checks/urls.py", line 13, in check_url_config
    return check_resolver(resolver)
  File "/home/wercules/.local/share/virtualenvs/medreport-3oUkA-aL/lib/python3.6/site-packages/django/core/checks/urls.py", line 23, in check_resolver
    return check_method()
  File "/home/wercules/.local/share/virtualenvs/medreport-3oUkA-aL/lib/python3.6/site-packages/django/urls/resolvers.py", line 398, in check
    for pattern in self.url_patterns:
  File "/home/wercules/.local/share/virtualenvs/medreport-3oUkA-aL/lib/python3.6/site-packages/django/utils/functional.py", line 80, in __get__
    res = instance.__dict__[self.name] = self.func(instance)
  File "/home/wercules/.local/share/virtualenvs/medreport-3oUkA-aL/lib/python3.6/site-packages/django/urls/resolvers.py", line 579, in url_patterns
    patterns = getattr(self.urlconf_module, "urlpatterns", self.urlconf_module)
  File "/home/wercules/.local/share/virtualenvs/medreport-3oUkA-aL/lib/python3.6/site-packages/django/utils/functional.py", line 80, in __get__
    res = instance.__dict__[self.name] = self.func(instance)
  File "/home/wercules/.local/share/virtualenvs/medreport-3oUkA-aL/lib/python3.6/site-packages/django/urls/resolvers.py", line 572, in urlconf_module
    return import_module(self.urlconf_name)
  File "/home/wercules/.local/share/virtualenvs/medreport-3oUkA-aL/lib64/python3.6/importlib/__init__.py", line 126, in import_module
    return _bootstrap._gcd_import(name[level:], package, level)
  File "<frozen importlib._bootstrap>", line 994, in _gcd_import
  File "<frozen importlib._bootstrap>", line 971, in _find_and_load
  File "<frozen importlib._bootstrap>", line 955, in _find_and_load_unlocked
  File "<frozen importlib._bootstrap>", line 665, in _load_unlocked
  File "<frozen importlib._bootstrap_external>", line 678, in exec_module
  File "<frozen importlib._bootstrap>", line 219, in _call_with_frames_removed
  File "/home/wercules/medreport/mrProject/urls.py", line 20, in <module>
    path('mr/', include('mrApp.urls')),
  File "/home/wercules/.local/share/virtualenvs/medreport-3oUkA-aL/lib/python3.6/site-packages/django/urls/conf.py", line 34, in include
    urlconf_module = import_module(urlconf_module)
  File "/home/wercules/.local/share/virtualenvs/medreport-3oUkA-aL/lib64/python3.6/importlib/__init__.py", line 126, in import_module
    return _bootstrap._gcd_import(name[level:], package, level)
  File "<frozen importlib._bootstrap>", line 994, in _gcd_import
  File "<frozen importlib._bootstrap>", line 971, in _find_and_load
  File "<frozen importlib._bootstrap>", line 955, in _find_and_load_unlocked
  File "<frozen importlib._bootstrap>", line 665, in _load_unlocked
  File "<frozen importlib._bootstrap_external>", line 678, in exec_module
  File "<frozen importlib._bootstrap>", line 219, in _call_with_frames_removed
  File "/home/wercules/medreport/mrApp/urls.py", line 14, in <module>
    path('pesquisar_atendimento', views.pesquisar_atendimento, name = 'pesquisar_atendimento'),
AttributeError: module 'mrApp.views' has no attribute 'pesquisar_atendimento'

/home/wercules/medreport/mrApp/urls.py changed, reloading.
Performing system checks...

Watching for file changes with StatReloader
Exception in thread django-main-thread:
Traceback (most recent call last):
  File "/usr/lib64/python3.6/threading.py", line 916, in _bootstrap_inner
    self.run()
  File "/usr/lib64/python3.6/threading.py", line 864, in run
    self._target(*self._args, **self._kwargs)
  File "/home/wercules/.local/share/virtualenvs/medreport-3oUkA-aL/lib/python3.6/site-packages/django/utils/autoreload.py", line 54, in wrapper
    fn(*args, **kwargs)
  File "/home/wercules/.local/share/virtualenvs/medreport-3oUkA-aL/lib/python3.6/site-packages/django/core/management/commands/runserver.py", line 117, in inner_run
    self.check(display_num_errors=True)
  File "/home/wercules/.local/share/virtualenvs/medreport-3oUkA-aL/lib/python3.6/site-packages/django/core/management/base.py", line 390, in check
    include_deployment_checks=include_deployment_checks,
  File "/home/wercules/.local/share/virtualenvs/medreport-3oUkA-aL/lib/python3.6/site-packages/django/core/management/base.py", line 377, in _run_checks
    return checks.run_checks(**kwargs)
  File "/home/wercules/.local/share/virtualenvs/medreport-3oUkA-aL/lib/python3.6/site-packages/django/core/checks/registry.py", line 72, in run_checks
    new_errors = check(app_configs=app_configs)
  File "/home/wercules/.local/share/virtualenvs/medreport-3oUkA-aL/lib/python3.6/site-packages/django/core/checks/urls.py", line 13, in check_url_config
    return check_resolver(resolver)
  File "/home/wercules/.local/share/virtualenvs/medreport-3oUkA-aL/lib/python3.6/site-packages/django/core/checks/urls.py", line 23, in check_resolver
    return check_method()
  File "/home/wercules/.local/share/virtualenvs/medreport-3oUkA-aL/lib/python3.6/site-packages/django/urls/resolvers.py", line 398, in check
    for pattern in self.url_patterns:
  File "/home/wercules/.local/share/virtualenvs/medreport-3oUkA-aL/lib/python3.6/site-packages/django/utils/functional.py", line 80, in __get__
    res = instance.__dict__[self.name] = self.func(instance)
  File "/home/wercules/.local/share/virtualenvs/medreport-3oUkA-aL/lib/python3.6/site-packages/django/urls/resolvers.py", line 579, in url_patterns
    patterns = getattr(self.urlconf_module, "urlpatterns", self.urlconf_module)
  File "/home/wercules/.local/share/virtualenvs/medreport-3oUkA-aL/lib/python3.6/site-packages/django/utils/functional.py", line 80, in __get__
    res = instance.__dict__[self.name] = self.func(instance)
  File "/home/wercules/.local/share/virtualenvs/medreport-3oUkA-aL/lib/python3.6/site-packages/django/urls/resolvers.py", line 572, in urlconf_module
    return import_module(self.urlconf_name)
  File "/home/wercules/.local/share/virtualenvs/medreport-3oUkA-aL/lib64/python3.6/importlib/__init__.py", line 126, in import_module
    return _bootstrap._gcd_import(name[level:], package, level)
  File "<frozen importlib._bootstrap>", line 994, in _gcd_import
  File "<frozen importlib._bootstrap>", line 971, in _find_and_load
  File "<frozen importlib._bootstrap>", line 955, in _find_and_load_unlocked
  File "<frozen importlib._bootstrap>", line 665, in _load_unlocked
  File "<frozen importlib._bootstrap_external>", line 678, in exec_module
  File "<frozen importlib._bootstrap>", line 219, in _call_with_frames_removed
  File "/home/wercules/medreport/mrProject/urls.py", line 20, in <module>
    path('mr/', include('mrApp.urls')),
  File "/home/wercules/.local/share/virtualenvs/medreport-3oUkA-aL/lib/python3.6/site-packages/django/urls/conf.py", line 34, in include
    urlconf_module = import_module(urlconf_module)
  File "/home/wercules/.local/share/virtualenvs/medreport-3oUkA-aL/lib64/python3.6/importlib/__init__.py", line 126, in import_module
    return _bootstrap._gcd_import(name[level:], package, level)
  File "<frozen importlib._bootstrap>", line 994, in _gcd_import
  File "<frozen importlib._bootstrap>", line 971, in _find_and_load
  File "<frozen importlib._bootstrap>", line 955, in _find_and_load_unlocked
  File "<frozen importlib._bootstrap>", line 665, in _load_unlocked
  File "<frozen importlib._bootstrap_external>", line 678, in exec_module
  File "<frozen importlib._bootstrap>", line 219, in _call_with_frames_removed
  File "/home/wercules/medreport/mrApp/urls.py", line 14, in <module>
    path('pesquisar_atendimento', views.pesquisar_atendimento, name = 'pesquisar_atendimento'),
AttributeError: module 'mrApp.views' has no attribute 'pesquisar_atendimento'

/home/wercules/medreport/mrApp/views.py changed, reloading.
Performing system checks...

Watching for file changes with StatReloader
Exception in thread django-main-thread:
Traceback (most recent call last):
  File "/usr/lib64/python3.6/threading.py", line 916, in _bootstrap_inner
    self.run()
  File "/usr/lib64/python3.6/threading.py", line 864, in run
    self._target(*self._args, **self._kwargs)
  File "/home/wercules/.local/share/virtualenvs/medreport-3oUkA-aL/lib/python3.6/site-packages/django/utils/autoreload.py", line 54, in wrapper
    fn(*args, **kwargs)
  File "/home/wercules/.local/share/virtualenvs/medreport-3oUkA-aL/lib/python3.6/site-packages/django/core/management/commands/runserver.py", line 117, in inner_run
    self.check(display_num_errors=True)
  File "/home/wercules/.local/share/virtualenvs/medreport-3oUkA-aL/lib/python3.6/site-packages/django/core/management/base.py", line 390, in check
    include_deployment_checks=include_deployment_checks,
  File "/home/wercules/.local/share/virtualenvs/medreport-3oUkA-aL/lib/python3.6/site-packages/django/core/management/base.py", line 377, in _run_checks
    return checks.run_checks(**kwargs)
  File "/home/wercules/.local/share/virtualenvs/medreport-3oUkA-aL/lib/python3.6/site-packages/django/core/checks/registry.py", line 72, in run_checks
    new_errors = check(app_configs=app_configs)
  File "/home/wercules/.local/share/virtualenvs/medreport-3oUkA-aL/lib/python3.6/site-packages/django/core/checks/urls.py", line 13, in check_url_config
    return check_resolver(resolver)
  File "/home/wercules/.local/share/virtualenvs/medreport-3oUkA-aL/lib/python3.6/site-packages/django/core/checks/urls.py", line 23, in check_resolver
    return check_method()
  File "/home/wercules/.local/share/virtualenvs/medreport-3oUkA-aL/lib/python3.6/site-packages/django/urls/resolvers.py", line 398, in check
    for pattern in self.url_patterns:
  File "/home/wercules/.local/share/virtualenvs/medreport-3oUkA-aL/lib/python3.6/site-packages/django/utils/functional.py", line 80, in __get__
    res = instance.__dict__[self.name] = self.func(instance)
  File "/home/wercules/.local/share/virtualenvs/medreport-3oUkA-aL/lib/python3.6/site-packages/django/urls/resolvers.py", line 579, in url_patterns
    patterns = getattr(self.urlconf_module, "urlpatterns", self.urlconf_module)
  File "/home/wercules/.local/share/virtualenvs/medreport-3oUkA-aL/lib/python3.6/site-packages/django/utils/functional.py", line 80, in __get__
    res = instance.__dict__[self.name] = self.func(instance)
  File "/home/wercules/.local/share/virtualenvs/medreport-3oUkA-aL/lib/python3.6/site-packages/django/urls/resolvers.py", line 572, in urlconf_module
    return import_module(self.urlconf_name)
  File "/home/wercules/.local/share/virtualenvs/medreport-3oUkA-aL/lib64/python3.6/importlib/__init__.py", line 126, in import_module
    return _bootstrap._gcd_import(name[level:], package, level)
  File "<frozen importlib._bootstrap>", line 994, in _gcd_import
  File "<frozen importlib._bootstrap>", line 971, in _find_and_load
  File "<frozen importlib._bootstrap>", line 955, in _find_and_load_unlocked
  File "<frozen importlib._bootstrap>", line 665, in _load_unlocked
  File "<frozen importlib._bootstrap_external>", line 678, in exec_module
  File "<frozen importlib._bootstrap>", line 219, in _call_with_frames_removed
  File "/home/wercules/medreport/mrProject/urls.py", line 20, in <module>
    path('mr/', include('mrApp.urls')),
  File "/home/wercules/.local/share/virtualenvs/medreport-3oUkA-aL/lib/python3.6/site-packages/django/urls/conf.py", line 34, in include
    urlconf_module = import_module(urlconf_module)
  File "/home/wercules/.local/share/virtualenvs/medreport-3oUkA-aL/lib64/python3.6/importlib/__init__.py", line 126, in import_module
    return _bootstrap._gcd_import(name[level:], package, level)
  File "<frozen importlib._bootstrap>", line 994, in _gcd_import
  File "<frozen importlib._bootstrap>", line 971, in _find_and_load
  File "<frozen importlib._bootstrap>", line 955, in _find_and_load_unlocked
  File "<frozen importlib._bootstrap>", line 665, in _load_unlocked
  File "<frozen importlib._bootstrap_external>", line 678, in exec_module
  File "<frozen importlib._bootstrap>", line 219, in _call_with_frames_removed
  File "/home/wercules/medreport/mrApp/urls.py", line 14, in <module>
    path('pesquisar_atendimento', views.pesquisar_atendimento, name = 'pesquisar_atendimento'),
AttributeError: module 'mrApp.views' has no attribute 'pesquisar_atendimento'

/home/wercules/medreport/mrApp/urls.py changed, reloading.
Performing system checks...

Watching for file changes with StatReloader
Exception in thread django-main-thread:
Traceback (most recent call last):
  File "/usr/lib64/python3.6/threading.py", line 916, in _bootstrap_inner
    self.run()
  File "/usr/lib64/python3.6/threading.py", line 864, in run
    self._target(*self._args, **self._kwargs)
  File "/home/wercules/.local/share/virtualenvs/medreport-3oUkA-aL/lib/python3.6/site-packages/django/utils/autoreload.py", line 54, in wrapper
    fn(*args, **kwargs)
  File "/home/wercules/.local/share/virtualenvs/medreport-3oUkA-aL/lib/python3.6/site-packages/django/core/management/commands/runserver.py", line 117, in inner_run
    self.check(display_num_errors=True)
  File "/home/wercules/.local/share/virtualenvs/medreport-3oUkA-aL/lib/python3.6/site-packages/django/core/management/base.py", line 390, in check
    include_deployment_checks=include_deployment_checks,
  File "/home/wercules/.local/share/virtualenvs/medreport-3oUkA-aL/lib/python3.6/site-packages/django/core/management/base.py", line 377, in _run_checks
    return checks.run_checks(**kwargs)
  File "/home/wercules/.local/share/virtualenvs/medreport-3oUkA-aL/lib/python3.6/site-packages/django/core/checks/registry.py", line 72, in run_checks
    new_errors = check(app_configs=app_configs)
  File "/home/wercules/.local/share/virtualenvs/medreport-3oUkA-aL/lib/python3.6/site-packages/django/core/checks/urls.py", line 13, in check_url_config
    return check_resolver(resolver)
  File "/home/wercules/.local/share/virtualenvs/medreport-3oUkA-aL/lib/python3.6/site-packages/django/core/checks/urls.py", line 23, in check_resolver
    return check_method()
  File "/home/wercules/.local/share/virtualenvs/medreport-3oUkA-aL/lib/python3.6/site-packages/django/urls/resolvers.py", line 398, in check
    for pattern in self.url_patterns:
  File "/home/wercules/.local/share/virtualenvs/medreport-3oUkA-aL/lib/python3.6/site-packages/django/utils/functional.py", line 80, in __get__
    res = instance.__dict__[self.name] = self.func(instance)
  File "/home/wercules/.local/share/virtualenvs/medreport-3oUkA-aL/lib/python3.6/site-packages/django/urls/resolvers.py", line 579, in url_patterns
    patterns = getattr(self.urlconf_module, "urlpatterns", self.urlconf_module)
  File "/home/wercules/.local/share/virtualenvs/medreport-3oUkA-aL/lib/python3.6/site-packages/django/utils/functional.py", line 80, in __get__
    res = instance.__dict__[self.name] = self.func(instance)
  File "/home/wercules/.local/share/virtualenvs/medreport-3oUkA-aL/lib/python3.6/site-packages/django/urls/resolvers.py", line 572, in urlconf_module
    return import_module(self.urlconf_name)
  File "/home/wercules/.local/share/virtualenvs/medreport-3oUkA-aL/lib64/python3.6/importlib/__init__.py", line 126, in import_module
    return _bootstrap._gcd_import(name[level:], package, level)
  File "<frozen importlib._bootstrap>", line 994, in _gcd_import
  File "<frozen importlib._bootstrap>", line 971, in _find_and_load
  File "<frozen importlib._bootstrap>", line 955, in _find_and_load_unlocked
  File "<frozen importlib._bootstrap>", line 665, in _load_unlocked
  File "<frozen importlib._bootstrap_external>", line 678, in exec_module
  File "<frozen importlib._bootstrap>", line 219, in _call_with_frames_removed
  File "/home/wercules/medreport/mrProject/urls.py", line 20, in <module>
    path('mr/', include('mrApp.urls')),
  File "/home/wercules/.local/share/virtualenvs/medreport-3oUkA-aL/lib/python3.6/site-packages/django/urls/conf.py", line 34, in include
    urlconf_module = import_module(urlconf_module)
  File "/home/wercules/.local/share/virtualenvs/medreport-3oUkA-aL/lib64/python3.6/importlib/__init__.py", line 126, in import_module
    return _bootstrap._gcd_import(name[level:], package, level)
  File "<frozen importlib._bootstrap>", line 994, in _gcd_import
  File "<frozen importlib._bootstrap>", line 971, in _find_and_load
  File "<frozen importlib._bootstrap>", line 955, in _find_and_load_unlocked
  File "<frozen importlib._bootstrap>", line 665, in _load_unlocked
  File "<frozen importlib._bootstrap_external>", line 678, in exec_module
  File "<frozen importlib._bootstrap>", line 219, in _call_with_frames_removed
  File "/home/wercules/medreport/mrApp/urls.py", line 14, in <module>
    path('pesquisar_datas_atendimento', views.pesquisar_atendimento, name = 'pesquisar_atendimento'),
AttributeError: module 'mrApp.views' has no attribute 'pesquisar_atendimento'

/home/wercules/medreport/mrApp/urls.py changed, reloading.
Performing system checks...

Watching for file changes with StatReloader
[07/Jun/2019 00:36:05] "GET /mr/ HTTP/1.1" 200 2439
Not Found: /resources/demos/style.css
[07/Jun/2019 00:36:05] "GET /resources/demos/style.css HTTP/1.1" 404 2241
Not Found: /favicon.ico
[07/Jun/2019 00:36:06] "GET /favicon.ico HTTP/1.1" 404 2199
[07/Jun/2019 00:36:10] "GET /mr/search?term=T HTTP/1.1" 200 36
[07/Jun/2019 00:36:10] "GET /mr/search?term=Ta HTTP/1.1" 200 36
Internal Server Error: /mr/procurar_paciente
Traceback (most recent call last):
  File "/home/wercules/.local/share/virtualenvs/medreport-3oUkA-aL/lib/python3.6/site-packages/django/core/handlers/exception.py", line 34, in inner
    response = get_response(request)
  File "/home/wercules/.local/share/virtualenvs/medreport-3oUkA-aL/lib/python3.6/site-packages/django/core/handlers/base.py", line 115, in _get_response
    response = self.process_exception_by_middleware(e, request)
  File "/home/wercules/.local/share/virtualenvs/medreport-3oUkA-aL/lib/python3.6/site-packages/django/core/handlers/base.py", line 113, in _get_response
    response = wrapped_callback(request, *callback_args, **callback_kwargs)
  File "/home/wercules/medreport/mrApp/views.py", line 68, in procurar_paciente
    return render(request, 'resultado_pesquisa_paciente.html', {'contexts': contexts})
  File "/home/wercules/.local/share/virtualenvs/medreport-3oUkA-aL/lib/python3.6/site-packages/django/shortcuts.py", line 36, in render
    content = loader.render_to_string(template_name, context, request, using=using)
  File "/home/wercules/.local/share/virtualenvs/medreport-3oUkA-aL/lib/python3.6/site-packages/django/template/loader.py", line 62, in render_to_string
    return template.render(context, request)
  File "/home/wercules/.local/share/virtualenvs/medreport-3oUkA-aL/lib/python3.6/site-packages/django/template/backends/django.py", line 61, in render
    return self.template.render(context)
  File "/home/wercules/.local/share/virtualenvs/medreport-3oUkA-aL/lib/python3.6/site-packages/django/template/base.py", line 171, in render
    return self._render(context)
  File "/home/wercules/.local/share/virtualenvs/medreport-3oUkA-aL/lib/python3.6/site-packages/django/template/base.py", line 163, in _render
    return self.nodelist.render(context)
  File "/home/wercules/.local/share/virtualenvs/medreport-3oUkA-aL/lib/python3.6/site-packages/django/template/base.py", line 937, in render
    bit = node.render_annotated(context)
  File "/home/wercules/.local/share/virtualenvs/medreport-3oUkA-aL/lib/python3.6/site-packages/django/template/base.py", line 904, in render_annotated
    return self.render(context)
  File "/home/wercules/.local/share/virtualenvs/medreport-3oUkA-aL/lib/python3.6/site-packages/django/template/loader_tags.py", line 150, in render
    return compiled_parent._render(context)
  File "/home/wercules/.local/share/virtualenvs/medreport-3oUkA-aL/lib/python3.6/site-packages/django/template/base.py", line 163, in _render
    return self.nodelist.render(context)
  File "/home/wercules/.local/share/virtualenvs/medreport-3oUkA-aL/lib/python3.6/site-packages/django/template/base.py", line 937, in render
    bit = node.render_annotated(context)
  File "/home/wercules/.local/share/virtualenvs/medreport-3oUkA-aL/lib/python3.6/site-packages/django/template/base.py", line 904, in render_annotated
    return self.render(context)
  File "/home/wercules/.local/share/virtualenvs/medreport-3oUkA-aL/lib/python3.6/site-packages/django/template/loader_tags.py", line 62, in render
    result = block.nodelist.render(context)
  File "/home/wercules/.local/share/virtualenvs/medreport-3oUkA-aL/lib/python3.6/site-packages/django/template/base.py", line 937, in render
    bit = node.render_annotated(context)
  File "/home/wercules/.local/share/virtualenvs/medreport-3oUkA-aL/lib/python3.6/site-packages/django/template/base.py", line 904, in render_annotated
    return self.render(context)
  File "/home/wercules/.local/share/virtualenvs/medreport-3oUkA-aL/lib/python3.6/site-packages/django/template/defaulttags.py", line 309, in render
    return nodelist.render(context)
  File "/home/wercules/.local/share/virtualenvs/medreport-3oUkA-aL/lib/python3.6/site-packages/django/template/base.py", line 937, in render
    bit = node.render_annotated(context)
  File "/home/wercules/.local/share/virtualenvs/medreport-3oUkA-aL/lib/python3.6/site-packages/django/template/base.py", line 904, in render_annotated
    return self.render(context)
  File "/home/wercules/.local/share/virtualenvs/medreport-3oUkA-aL/lib/python3.6/site-packages/django/template/defaulttags.py", line 209, in render
    nodelist.append(node.render_annotated(context))
  File "/home/wercules/.local/share/virtualenvs/medreport-3oUkA-aL/lib/python3.6/site-packages/django/template/base.py", line 904, in render_annotated
    return self.render(context)
  File "/home/wercules/.local/share/virtualenvs/medreport-3oUkA-aL/lib/python3.6/site-packages/django/template/defaulttags.py", line 443, in render
    url = reverse(view_name, args=args, kwargs=kwargs, current_app=current_app)
  File "/home/wercules/.local/share/virtualenvs/medreport-3oUkA-aL/lib/python3.6/site-packages/django/urls/base.py", line 90, in reverse
    return iri_to_uri(resolver._reverse_with_prefix(view, prefix, *args, **kwargs))
  File "/home/wercules/.local/share/virtualenvs/medreport-3oUkA-aL/lib/python3.6/site-packages/django/urls/resolvers.py", line 668, in _reverse_with_prefix
    raise NoReverseMatch(msg)
django.urls.exceptions.NoReverseMatch: Reverse for 'pesquisar_atendimento' not found. 'pesquisar_atendimento' is not a valid view function or pattern name.
[07/Jun/2019 00:36:13] "POST /mr/procurar_paciente HTTP/1.1" 500 180648
Not Found: /favicon.ico
[07/Jun/2019 00:36:14] "GET /favicon.ico HTTP/1.1" 404 2199
[07/Jun/2019 00:40:28] "POST /mr/procurar_paciente HTTP/1.1" 200 2175
Not Found: /resources/demos/style.css
[07/Jun/2019 00:40:29] "GET /resources/demos/style.css HTTP/1.1" 404 2241
Not Found: /favicon.ico
[07/Jun/2019 00:40:29] "GET /favicon.ico HTTP/1.1" 404 2199
[07/Jun/2019 00:40:33] "POST /mr/pesquisar_datas_atendimento HTTP/1.1" 200 2570
Not Found: /resources/demos/style.css
[07/Jun/2019 00:40:33] "GET /resources/demos/style.css HTTP/1.1" 404 2241
Internal Server Error: /mr/pesquisar_conteudo_atendimento
Traceback (most recent call last):
  File "/home/wercules/.local/share/virtualenvs/medreport-3oUkA-aL/lib/python3.6/site-packages/django/template/base.py", line 470, in parse
    compile_func = self.tags[command]
KeyError: 'endfor'

During handling of the above exception, another exception occurred:

Traceback (most recent call last):
  File "/home/wercules/.local/share/virtualenvs/medreport-3oUkA-aL/lib/python3.6/site-packages/django/core/handlers/exception.py", line 34, in inner
    response = get_response(request)
  File "/home/wercules/.local/share/virtualenvs/medreport-3oUkA-aL/lib/python3.6/site-packages/django/core/handlers/base.py", line 115, in _get_response
    response = self.process_exception_by_middleware(e, request)
  File "/home/wercules/.local/share/virtualenvs/medreport-3oUkA-aL/lib/python3.6/site-packages/django/core/handlers/base.py", line 113, in _get_response
    response = wrapped_callback(request, *callback_args, **callback_kwargs)
  File "/home/wercules/medreport/mrApp/views.py", line 102, in pesquisar_conteudo_atendimento
    return render(request, 'conteudo_atendimento.html', {'context':context})
  File "/home/wercules/.local/share/virtualenvs/medreport-3oUkA-aL/lib/python3.6/site-packages/django/shortcuts.py", line 36, in render
    content = loader.render_to_string(template_name, context, request, using=using)
  File "/home/wercules/.local/share/virtualenvs/medreport-3oUkA-aL/lib/python3.6/site-packages/django/template/loader.py", line 61, in render_to_string
    template = get_template(template_name, using=using)
  File "/home/wercules/.local/share/virtualenvs/medreport-3oUkA-aL/lib/python3.6/site-packages/django/template/loader.py", line 15, in get_template
    return engine.get_template(template_name)
  File "/home/wercules/.local/share/virtualenvs/medreport-3oUkA-aL/lib/python3.6/site-packages/django/template/backends/django.py", line 34, in get_template
    return Template(self.engine.get_template(template_name), self)
  File "/home/wercules/.local/share/virtualenvs/medreport-3oUkA-aL/lib/python3.6/site-packages/django/template/engine.py", line 143, in get_template
    template, origin = self.find_template(template_name)
  File "/home/wercules/.local/share/virtualenvs/medreport-3oUkA-aL/lib/python3.6/site-packages/django/template/engine.py", line 125, in find_template
    template = loader.get_template(name, skip=skip)
  File "/home/wercules/.local/share/virtualenvs/medreport-3oUkA-aL/lib/python3.6/site-packages/django/template/loaders/base.py", line 30, in get_template
    contents, origin, origin.template_name, self.engine,
  File "/home/wercules/.local/share/virtualenvs/medreport-3oUkA-aL/lib/python3.6/site-packages/django/template/base.py", line 156, in __init__
    self.nodelist = self.compile_nodelist()
  File "/home/wercules/.local/share/virtualenvs/medreport-3oUkA-aL/lib/python3.6/site-packages/django/template/base.py", line 194, in compile_nodelist
    return parser.parse()
  File "/home/wercules/.local/share/virtualenvs/medreport-3oUkA-aL/lib/python3.6/site-packages/django/template/base.py", line 478, in parse
    raise self.error(token, e)
  File "/home/wercules/.local/share/virtualenvs/medreport-3oUkA-aL/lib/python3.6/site-packages/django/template/base.py", line 476, in parse
    compiled_result = compile_func(self, token)
  File "/home/wercules/.local/share/virtualenvs/medreport-3oUkA-aL/lib/python3.6/site-packages/django/template/loader_tags.py", line 266, in do_extends
    nodelist = parser.parse()
  File "/home/wercules/.local/share/virtualenvs/medreport-3oUkA-aL/lib/python3.6/site-packages/django/template/base.py", line 478, in parse
    raise self.error(token, e)
  File "/home/wercules/.local/share/virtualenvs/medreport-3oUkA-aL/lib/python3.6/site-packages/django/template/base.py", line 476, in parse
    compiled_result = compile_func(self, token)
  File "/home/wercules/.local/share/virtualenvs/medreport-3oUkA-aL/lib/python3.6/site-packages/django/template/loader_tags.py", line 209, in do_block
    nodelist = parser.parse(('endblock',))
  File "/home/wercules/.local/share/virtualenvs/medreport-3oUkA-aL/lib/python3.6/site-packages/django/template/base.py", line 478, in parse
    raise self.error(token, e)
  File "/home/wercules/.local/share/virtualenvs/medreport-3oUkA-aL/lib/python3.6/site-packages/django/template/base.py", line 476, in parse
    compiled_result = compile_func(self, token)
  File "/home/wercules/.local/share/virtualenvs/medreport-3oUkA-aL/lib/python3.6/site-packages/django/template/defaulttags.py", line 952, in do_if
    nodelist = parser.parse(('elif', 'else', 'endif'))
  File "/home/wercules/.local/share/virtualenvs/medreport-3oUkA-aL/lib/python3.6/site-packages/django/template/base.py", line 472, in parse
    self.invalid_block_tag(token, command, parse_until)
  File "/home/wercules/.local/share/virtualenvs/medreport-3oUkA-aL/lib/python3.6/site-packages/django/template/base.py", line 528, in invalid_block_tag
    get_text_list(["'%s'" % p for p in parse_until], 'or'),
django.template.exceptions.TemplateSyntaxError: Invalid block tag on line 30: 'endfor', expected 'elif', 'else' or 'endif'. Did you forget to register or load this tag?
[07/Jun/2019 00:40:38] "POST /mr/pesquisar_conteudo_atendimento HTTP/1.1" 500 178732
Not Found: /favicon.ico
[07/Jun/2019 00:40:39] "GET /favicon.ico HTTP/1.1" 404 2199
Internal Server Error: /mr/pesquisar_conteudo_atendimento
Traceback (most recent call last):
  File "/home/wercules/.local/share/virtualenvs/medreport-3oUkA-aL/lib/python3.6/site-packages/django/core/handlers/exception.py", line 34, in inner
    response = get_response(request)
  File "/home/wercules/.local/share/virtualenvs/medreport-3oUkA-aL/lib/python3.6/site-packages/django/core/handlers/base.py", line 115, in _get_response
    response = self.process_exception_by_middleware(e, request)
  File "/home/wercules/.local/share/virtualenvs/medreport-3oUkA-aL/lib/python3.6/site-packages/django/core/handlers/base.py", line 113, in _get_response
    response = wrapped_callback(request, *callback_args, **callback_kwargs)
  File "/home/wercules/medreport/mrApp/views.py", line 102, in pesquisar_conteudo_atendimento
    return render(request, 'conteudo_atendimento.html', {'context':context})
  File "/home/wercules/.local/share/virtualenvs/medreport-3oUkA-aL/lib/python3.6/site-packages/django/shortcuts.py", line 36, in render
    content = loader.render_to_string(template_name, context, request, using=using)
  File "/home/wercules/.local/share/virtualenvs/medreport-3oUkA-aL/lib/python3.6/site-packages/django/template/loader.py", line 62, in render_to_string
    return template.render(context, request)
  File "/home/wercules/.local/share/virtualenvs/medreport-3oUkA-aL/lib/python3.6/site-packages/django/template/backends/django.py", line 61, in render
    return self.template.render(context)
  File "/home/wercules/.local/share/virtualenvs/medreport-3oUkA-aL/lib/python3.6/site-packages/django/template/base.py", line 171, in render
    return self._render(context)
  File "/home/wercules/.local/share/virtualenvs/medreport-3oUkA-aL/lib/python3.6/site-packages/django/template/base.py", line 163, in _render
    return self.nodelist.render(context)
  File "/home/wercules/.local/share/virtualenvs/medreport-3oUkA-aL/lib/python3.6/site-packages/django/template/base.py", line 937, in render
    bit = node.render_annotated(context)
  File "/home/wercules/.local/share/virtualenvs/medreport-3oUkA-aL/lib/python3.6/site-packages/django/template/base.py", line 904, in render_annotated
    return self.render(context)
  File "/home/wercules/.local/share/virtualenvs/medreport-3oUkA-aL/lib/python3.6/site-packages/django/template/loader_tags.py", line 150, in render
    return compiled_parent._render(context)
  File "/home/wercules/.local/share/virtualenvs/medreport-3oUkA-aL/lib/python3.6/site-packages/django/template/base.py", line 163, in _render
    return self.nodelist.render(context)
  File "/home/wercules/.local/share/virtualenvs/medreport-3oUkA-aL/lib/python3.6/site-packages/django/template/base.py", line 937, in render
    bit = node.render_annotated(context)
  File "/home/wercules/.local/share/virtualenvs/medreport-3oUkA-aL/lib/python3.6/site-packages/django/template/base.py", line 904, in render_annotated
    return self.render(context)
  File "/home/wercules/.local/share/virtualenvs/medreport-3oUkA-aL/lib/python3.6/site-packages/django/template/loader_tags.py", line 62, in render
    result = block.nodelist.render(context)
  File "/home/wercules/.local/share/virtualenvs/medreport-3oUkA-aL/lib/python3.6/site-packages/django/template/base.py", line 937, in render
    bit = node.render_annotated(context)
  File "/home/wercules/.local/share/virtualenvs/medreport-3oUkA-aL/lib/python3.6/site-packages/django/template/base.py", line 904, in render_annotated
    return self.render(context)
  File "/home/wercules/.local/share/virtualenvs/medreport-3oUkA-aL/lib/python3.6/site-packages/django/template/defaulttags.py", line 309, in render
    return nodelist.render(context)
  File "/home/wercules/.local/share/virtualenvs/medreport-3oUkA-aL/lib/python3.6/site-packages/django/template/base.py", line 937, in render
    bit = node.render_annotated(context)
  File "/home/wercules/.local/share/virtualenvs/medreport-3oUkA-aL/lib/python3.6/site-packages/django/template/base.py", line 904, in render_annotated
    return self.render(context)
  File "/home/wercules/.local/share/virtualenvs/medreport-3oUkA-aL/lib/python3.6/site-packages/django/template/defaulttags.py", line 443, in render
    url = reverse(view_name, args=args, kwargs=kwargs, current_app=current_app)
  File "/home/wercules/.local/share/virtualenvs/medreport-3oUkA-aL/lib/python3.6/site-packages/django/urls/base.py", line 90, in reverse
    return iri_to_uri(resolver._reverse_with_prefix(view, prefix, *args, **kwargs))
  File "/home/wercules/.local/share/virtualenvs/medreport-3oUkA-aL/lib/python3.6/site-packages/django/urls/resolvers.py", line 668, in _reverse_with_prefix
    raise NoReverseMatch(msg)
django.urls.exceptions.NoReverseMatch: Reverse for 'pesquisar_atendimento' not found. 'pesquisar_atendimento' is not a valid view function or pattern name.
[07/Jun/2019 00:41:07] "POST /mr/pesquisar_conteudo_atendimento HTTP/1.1" 500 172692
Not Found: /favicon.ico
[07/Jun/2019 00:41:08] "GET /favicon.ico HTTP/1.1" 404 2199
[07/Jun/2019 00:41:22] "POST /mr/pesquisar_datas_atendimento HTTP/1.1" 200 2570
[07/Jun/2019 00:41:22] "GET /static/js/main.js HTTP/1.1" 304 0
Not Found: /resources/demos/style.css
[07/Jun/2019 00:41:22] "GET /resources/demos/style.css HTTP/1.1" 404 2241
[07/Jun/2019 00:41:22] "GET /static/css/style.css HTTP/1.1" 200 532
Not Found: /favicon.ico
[07/Jun/2019 00:41:23] "GET /favicon.ico HTTP/1.1" 404 2199
Internal Server Error: /mr/pesquisar_conteudo_atendimento
Traceback (most recent call last):
  File "/home/wercules/.local/share/virtualenvs/medreport-3oUkA-aL/lib/python3.6/site-packages/django/core/handlers/exception.py", line 34, in inner
    response = get_response(request)
  File "/home/wercules/.local/share/virtualenvs/medreport-3oUkA-aL/lib/python3.6/site-packages/django/core/handlers/base.py", line 115, in _get_response
    response = self.process_exception_by_middleware(e, request)
  File "/home/wercules/.local/share/virtualenvs/medreport-3oUkA-aL/lib/python3.6/site-packages/django/core/handlers/base.py", line 113, in _get_response
    response = wrapped_callback(request, *callback_args, **callback_kwargs)
  File "/home/wercules/medreport/mrApp/views.py", line 102, in pesquisar_conteudo_atendimento
    return render(request, 'conteudo_atendimento.html', {'context':context})
  File "/home/wercules/.local/share/virtualenvs/medreport-3oUkA-aL/lib/python3.6/site-packages/django/shortcuts.py", line 36, in render
    content = loader.render_to_string(template_name, context, request, using=using)
  File "/home/wercules/.local/share/virtualenvs/medreport-3oUkA-aL/lib/python3.6/site-packages/django/template/loader.py", line 62, in render_to_string
    return template.render(context, request)
  File "/home/wercules/.local/share/virtualenvs/medreport-3oUkA-aL/lib/python3.6/site-packages/django/template/backends/django.py", line 61, in render
    return self.template.render(context)
  File "/home/wercules/.local/share/virtualenvs/medreport-3oUkA-aL/lib/python3.6/site-packages/django/template/base.py", line 171, in render
    return self._render(context)
  File "/home/wercules/.local/share/virtualenvs/medreport-3oUkA-aL/lib/python3.6/site-packages/django/template/base.py", line 163, in _render
    return self.nodelist.render(context)
  File "/home/wercules/.local/share/virtualenvs/medreport-3oUkA-aL/lib/python3.6/site-packages/django/template/base.py", line 937, in render
    bit = node.render_annotated(context)
  File "/home/wercules/.local/share/virtualenvs/medreport-3oUkA-aL/lib/python3.6/site-packages/django/template/base.py", line 904, in render_annotated
    return self.render(context)
  File "/home/wercules/.local/share/virtualenvs/medreport-3oUkA-aL/lib/python3.6/site-packages/django/template/loader_tags.py", line 150, in render
    return compiled_parent._render(context)
  File "/home/wercules/.local/share/virtualenvs/medreport-3oUkA-aL/lib/python3.6/site-packages/django/template/base.py", line 163, in _render
    return self.nodelist.render(context)
  File "/home/wercules/.local/share/virtualenvs/medreport-3oUkA-aL/lib/python3.6/site-packages/django/template/base.py", line 937, in render
    bit = node.render_annotated(context)
  File "/home/wercules/.local/share/virtualenvs/medreport-3oUkA-aL/lib/python3.6/site-packages/django/template/base.py", line 904, in render_annotated
    return self.render(context)
  File "/home/wercules/.local/share/virtualenvs/medreport-3oUkA-aL/lib/python3.6/site-packages/django/template/loader_tags.py", line 62, in render
    result = block.nodelist.render(context)
  File "/home/wercules/.local/share/virtualenvs/medreport-3oUkA-aL/lib/python3.6/site-packages/django/template/base.py", line 937, in render
    bit = node.render_annotated(context)
  File "/home/wercules/.local/share/virtualenvs/medreport-3oUkA-aL/lib/python3.6/site-packages/django/template/base.py", line 904, in render_annotated
    return self.render(context)
  File "/home/wercules/.local/share/virtualenvs/medreport-3oUkA-aL/lib/python3.6/site-packages/django/template/defaulttags.py", line 309, in render
    return nodelist.render(context)
  File "/home/wercules/.local/share/virtualenvs/medreport-3oUkA-aL/lib/python3.6/site-packages/django/template/base.py", line 937, in render
    bit = node.render_annotated(context)
  File "/home/wercules/.local/share/virtualenvs/medreport-3oUkA-aL/lib/python3.6/site-packages/django/template/base.py", line 904, in render_annotated
    return self.render(context)
  File "/home/wercules/.local/share/virtualenvs/medreport-3oUkA-aL/lib/python3.6/site-packages/django/template/defaulttags.py", line 443, in render
    url = reverse(view_name, args=args, kwargs=kwargs, current_app=current_app)
  File "/home/wercules/.local/share/virtualenvs/medreport-3oUkA-aL/lib/python3.6/site-packages/django/urls/base.py", line 90, in reverse
    return iri_to_uri(resolver._reverse_with_prefix(view, prefix, *args, **kwargs))
  File "/home/wercules/.local/share/virtualenvs/medreport-3oUkA-aL/lib/python3.6/site-packages/django/urls/resolvers.py", line 668, in _reverse_with_prefix
    raise NoReverseMatch(msg)
django.urls.exceptions.NoReverseMatch: Reverse for 'pesquisar_atendimento' not found. 'pesquisar_atendimento' is not a valid view function or pattern name.
[07/Jun/2019 00:41:25] "POST /mr/pesquisar_conteudo_atendimento HTTP/1.1" 500 172692
[07/Jun/2019 00:42:39] "POST /mr/pesquisar_conteudo_atendimento HTTP/1.1" 200 1838
Not Found: /resources/demos/style.css
[07/Jun/2019 00:42:40] "GET /resources/demos/style.css HTTP/1.1" 404 2241
[07/Jun/2019 00:42:40] "GET /static/js/main.js HTTP/1.1" 304 0
[07/Jun/2019 00:42:40] "GET /static/css/style.css HTTP/1.1" 200 532
Invalid HTTP_HOST header: 'rodrigocordovil.com.br'. You may need to add 'rodrigocordovil.com.br' to ALLOWED_HOSTS.
Bad Request: /
[07/Jun/2019 00:43:46] "GET / HTTP/1.1" 400 63632
[07/Jun/2019 00:45:20] "POST /mr/pesquisar_conteudo_atendimento HTTP/1.1" 200 1740
[07/Jun/2019 00:45:21] "GET /static/js/main.js HTTP/1.1" 304 0
Not Found: /resources/demos/style.css
[07/Jun/2019 00:45:21] "GET /resources/demos/style.css HTTP/1.1" 404 2241
[07/Jun/2019 00:45:21] "GET /static/css/style.css HTTP/1.1" 200 532
Not Found: /favicon.ico
[07/Jun/2019 00:45:22] "GET /favicon.ico HTTP/1.1" 404 2199
[07/Jun/2019 00:45:59] "POST /mr/pesquisar_conteudo_atendimento HTTP/1.1" 200 1742
Not Found: /resources/demos/style.css
[07/Jun/2019 00:45:59] "GET /resources/demos/style.css HTTP/1.1" 404 2241
Not Found: /favicon.ico
[07/Jun/2019 00:46:00] "GET /favicon.ico HTTP/1.1" 404 2199
[07/Jun/2019 00:46:26] "POST /mr/pesquisar_conteudo_atendimento HTTP/1.1" 200 1756
[07/Jun/2019 00:46:27] "GET /static/js/main.js HTTP/1.1" 304 0
Not Found: /resources/demos/style.css
[07/Jun/2019 00:46:27] "GET /resources/demos/style.css HTTP/1.1" 404 2241
[07/Jun/2019 00:46:27] "GET /static/css/style.css HTTP/1.1" 304 0
Not Found: /favicon.ico
[07/Jun/2019 00:46:27] "GET /favicon.ico HTTP/1.1" 404 2199
[07/Jun/2019 00:46:52] "POST /mr/pesquisar_conteudo_atendimento HTTP/1.1" 200 1755
[07/Jun/2019 00:46:52] "GET /static/css/style.css HTTP/1.1" 304 0
Not Found: /resources/demos/style.css
[07/Jun/2019 00:46:52] "GET /resources/demos/style.css HTTP/1.1" 404 2241
[07/Jun/2019 00:46:53] "GET /static/js/main.js HTTP/1.1" 304 0
Not Found: /favicon.ico
[07/Jun/2019 00:46:53] "GET /favicon.ico HTTP/1.1" 404 2199
[07/Jun/2019 00:52:13] "POST /mr/pesquisar_conteudo_atendimento HTTP/1.1" 200 1755
Not Found: /resources/demos/style.css
[07/Jun/2019 00:52:14] "GET /resources/demos/style.css HTTP/1.1" 404 2241
Not Found: /favicon.ico
[07/Jun/2019 00:52:14] "GET /favicon.ico HTTP/1.1" 404 2199
Not Found: /favicon.ico
[07/Jun/2019 00:53:17] "GET /favicon.ico HTTP/1.1" 404 2199
[07/Jun/2019 00:53:23] "POST /mr/pesquisar_conteudo_atendimento HTTP/1.1" 200 1755
Not Found: /resources/demos/style.css
[07/Jun/2019 00:53:23] "GET /resources/demos/style.css HTTP/1.1" 404 2241
Not Found: /favicon.ico
[07/Jun/2019 00:53:25] "GET /favicon.ico HTTP/1.1" 404 2199
Not Found: /resources/demos/style.css
[07/Jun/2019 00:54:23] "GET /resources/demos/style.css HTTP/1.1" 404 2241
[07/Jun/2019 00:57:21] "GET /mr/search?term=Tadeu%20da%20Silv HTTP/1.1" 200 18
[07/Jun/2019 00:57:23] "GET /mr/search?term=W HTTP/1.1" 200 21
[07/Jun/2019 00:57:23] "GET /mr/search?term=Wer HTTP/1.1" 200 21
[07/Jun/2019 00:57:27] "POST /mr/procurar_paciente HTTP/1.1" 200 2177
Not Found: /resources/demos/style.css
[07/Jun/2019 00:57:28] "GET /resources/demos/style.css HTTP/1.1" 404 2241
Not Found: /favicon.ico
[07/Jun/2019 00:57:28] "GET /favicon.ico HTTP/1.1" 404 2199
[07/Jun/2019 00:57:31] "POST /mr/pesquisar_datas_atendimento HTTP/1.1" 200 1749
Not Found: /resources/demos/style.css
[07/Jun/2019 00:57:31] "GET /resources/demos/style.css HTTP/1.1" 404 2241
Invalid HTTP_HOST header: 'www.cardiobemestar.com.br:8000'. You may need to add 'www.cardiobemestar.com.br' to ALLOWED_HOSTS.
Bad Request: /mr
[07/Jun/2019 00:57:39] "GET /mr HTTP/1.1" 400 65783
----------------------------------------
Exception happened during processing of request from ('185.156.177.242', 22296)
[07/Jun/2019 01:18:56] code 400, message Bad HTTP/0.9 request type ('\x03\x00\x00*%à\x00\x00\x00\x00\x00Cookie:')
[07/Jun/2019 01:18:56] "  *%à     Cookie: mstshash=Test" 400 -
[07/Jun/2019 01:18:57] code 400, message Bad HTTP/0.9 request type ('\x03\x00\x00*%à\x00\x00\x00\x00\x00Cookie:')
[07/Jun/2019 01:18:57] "  *%à     Cookie: mstshash=Test" 400 -
Traceback (most recent call last):
  File "/usr/lib64/python3.6/socketserver.py", line 654, in process_request_thread
    self.finish_request(request, client_address)
  File "/usr/lib64/python3.6/socketserver.py", line 364, in finish_request
    self.RequestHandlerClass(request, client_address, self)
  File "/usr/lib64/python3.6/socketserver.py", line 724, in __init__
    self.handle()
  File "/home/wercules/.local/share/virtualenvs/medreport-3oUkA-aL/lib/python3.6/site-packages/django/core/servers/basehttp.py", line 169, in handle
    self.handle_one_request()
  File "/home/wercules/.local/share/virtualenvs/medreport-3oUkA-aL/lib/python3.6/site-packages/django/core/servers/basehttp.py", line 179, in handle_one_request
    self.raw_requestline = self.rfile.readline(65537)
  File "/usr/lib64/python3.6/socket.py", line 586, in readinto
    return self._sock.recv_into(b)
ConnectionResetError: [Errno 104] Connection reset by peer
----------------------------------------
Invalid HTTP_HOST header: 'www.drantoniobacelar.com.br'. You may need to add 'www.drantoniobacelar.com.br' to ALLOWED_HOSTS.
Bad Request: /
[07/Jun/2019 08:48:38] "GET / HTTP/1.1" 400 63708
Invalid HTTP_HOST header: 'www.crharmonia.com.br'. You may need to add 'www.crharmonia.com.br' to ALLOWED_HOSTS.
Bad Request: /
[07/Jun/2019 13:47:08] "GET / HTTP/1.1" 400 63617
Not Found: /
[07/Jun/2019 14:38:34] "GET / HTTP/1.1" 404 2143
Invalid HTTP_HOST header: '8000'. You may need to add '8000' to ALLOWED_HOSTS.
Bad Request: /
[07/Jun/2019 16:14:06] "GET / HTTP/1.1" 400 63526
Invalid HTTP_HOST header: 'www.clinicarharmonia.com.br'. You may need to add 'www.clinicarharmonia.com.br' to ALLOWED_HOSTS.
Bad Request: /
[07/Jun/2019 16:17:44] "GET / HTTP/1.1" 400 63707
[07/Jun/2019 17:44:37] "GET /mr/ HTTP/1.1" 200 2439
Not Found: /resources/demos/style.css
[07/Jun/2019 17:44:38] "GET /resources/demos/style.css HTTP/1.1" 404 2241
[07/Jun/2019 17:44:38] "GET /static/js/main.js HTTP/1.1" 200 123
Not Found: /favicon.ico
[07/Jun/2019 17:44:39] "GET /favicon.ico HTTP/1.1" 404 2199
[07/Jun/2019 17:45:10] "GET /mr/search?term=we HTTP/1.1" 200 2
[07/Jun/2019 17:45:12] "GET /mr/search?term=wer HTTP/1.1" 200 2
[07/Jun/2019 17:45:16] "POST /mr/procurar_paciente HTTP/1.1" 200 1727
Not Found: /resources/demos/style.css
[07/Jun/2019 17:45:16] "GET /resources/demos/style.css HTTP/1.1" 404 2241
Not Found: /favicon.ico
[07/Jun/2019 17:45:16] "GET /favicon.ico HTTP/1.1" 404 2199
[07/Jun/2019 17:45:21] "GET /mr/search?term=wer HTTP/1.1" 200 2
[07/Jun/2019 17:45:21] "GET /mr/search?term=wer HTTP/1.1" 200 2
[07/Jun/2019 17:45:22] "GET /mr/search?term=t HTTP/1.1" 200 2
[07/Jun/2019 17:45:22] "GET /mr/search?term=ta HTTP/1.1" 200 2
[07/Jun/2019 17:45:23] "GET /mr/search?term=t HTTP/1.1" 200 2
[07/Jun/2019 17:45:24] "GET /mr/search?term=T HTTP/1.1" 200 36
[07/Jun/2019 17:45:24] "GET /mr/search?term=TA HTTP/1.1" 200 2
[07/Jun/2019 17:45:25] "GET /mr/search?term=T HTTP/1.1" 200 36
[07/Jun/2019 17:45:26] "GET /mr/search?term=Ta HTTP/1.1" 200 36
[07/Jun/2019 17:45:30] "POST /mr/procurar_paciente HTTP/1.1" 200 2175
Not Found: /resources/demos/style.css
[07/Jun/2019 17:45:30] "GET /resources/demos/style.css HTTP/1.1" 404 2241
Not Found: /favicon.ico
[07/Jun/2019 17:45:31] "GET /favicon.ico HTTP/1.1" 404 2199
[07/Jun/2019 17:45:35] "POST /mr/pesquisar_datas_atendimento HTTP/1.1" 200 2570
Not Found: /resources/demos/style.css
[07/Jun/2019 17:45:36] "GET /resources/demos/style.css HTTP/1.1" 404 2241
Not Found: /favicon.ico
[07/Jun/2019 17:45:36] "GET /favicon.ico HTTP/1.1" 404 2199
/home/wercules/medreport/mrApp/forms.py changed, reloading.
Performing system checks...

System check identified no issues (0 silenced).
June 07, 2019 - 00:35:39
Django version 2.2.1, using settings 'mrProject.settings'
Starting development server at http://cardiobemestar.com.br:8000/
Quit the server with CONTROL-C.
Watching for file changes with StatReloader
Exception in thread django-main-thread:
Traceback (most recent call last):
  File "/usr/lib64/python3.6/threading.py", line 916, in _bootstrap_inner
    self.run()
  File "/usr/lib64/python3.6/threading.py", line 864, in run
    self._target(*self._args, **self._kwargs)
  File "/home/wercules/.local/share/virtualenvs/medreport-3oUkA-aL/lib/python3.6/site-packages/django/utils/autoreload.py", line 54, in wrapper
    fn(*args, **kwargs)
  File "/home/wercules/.local/share/virtualenvs/medreport-3oUkA-aL/lib/python3.6/site-packages/django/core/management/commands/runserver.py", line 117, in inner_run
    self.check(display_num_errors=True)
  File "/home/wercules/.local/share/virtualenvs/medreport-3oUkA-aL/lib/python3.6/site-packages/django/core/management/base.py", line 390, in check
    include_deployment_checks=include_deployment_checks,
  File "/home/wercules/.local/share/virtualenvs/medreport-3oUkA-aL/lib/python3.6/site-packages/django/core/management/base.py", line 377, in _run_checks
    return checks.run_checks(**kwargs)
  File "/home/wercules/.local/share/virtualenvs/medreport-3oUkA-aL/lib/python3.6/site-packages/django/core/checks/registry.py", line 72, in run_checks
    new_errors = check(app_configs=app_configs)
  File "/home/wercules/.local/share/virtualenvs/medreport-3oUkA-aL/lib/python3.6/site-packages/django/core/checks/urls.py", line 40, in check_url_namespaces_unique
    all_namespaces = _load_all_namespaces(resolver)
  File "/home/wercules/.local/share/virtualenvs/medreport-3oUkA-aL/lib/python3.6/site-packages/django/core/checks/urls.py", line 57, in _load_all_namespaces
    url_patterns = getattr(resolver, 'url_patterns', [])
  File "/home/wercules/.local/share/virtualenvs/medreport-3oUkA-aL/lib/python3.6/site-packages/django/utils/functional.py", line 80, in __get__
    res = instance.__dict__[self.name] = self.func(instance)
  File "/home/wercules/.local/share/virtualenvs/medreport-3oUkA-aL/lib/python3.6/site-packages/django/urls/resolvers.py", line 579, in url_patterns
    patterns = getattr(self.urlconf_module, "urlpatterns", self.urlconf_module)
  File "/home/wercules/.local/share/virtualenvs/medreport-3oUkA-aL/lib/python3.6/site-packages/django/utils/functional.py", line 80, in __get__
    res = instance.__dict__[self.name] = self.func(instance)
  File "/home/wercules/.local/share/virtualenvs/medreport-3oUkA-aL/lib/python3.6/site-packages/django/urls/resolvers.py", line 572, in urlconf_module
    return import_module(self.urlconf_name)
  File "/home/wercules/.local/share/virtualenvs/medreport-3oUkA-aL/lib64/python3.6/importlib/__init__.py", line 126, in import_module
    return _bootstrap._gcd_import(name[level:], package, level)
  File "<frozen importlib._bootstrap>", line 994, in _gcd_import
  File "<frozen importlib._bootstrap>", line 971, in _find_and_load
  File "<frozen importlib._bootstrap>", line 955, in _find_and_load_unlocked
  File "<frozen importlib._bootstrap>", line 665, in _load_unlocked
  File "<frozen importlib._bootstrap_external>", line 678, in exec_module
  File "<frozen importlib._bootstrap>", line 219, in _call_with_frames_removed
  File "/home/wercules/medreport/mrProject/urls.py", line 20, in <module>
    path('mr/', include('mrApp.urls')),
  File "/home/wercules/.local/share/virtualenvs/medreport-3oUkA-aL/lib/python3.6/site-packages/django/urls/conf.py", line 34, in include
    urlconf_module = import_module(urlconf_module)
  File "/home/wercules/.local/share/virtualenvs/medreport-3oUkA-aL/lib64/python3.6/importlib/__init__.py", line 126, in import_module
    return _bootstrap._gcd_import(name[level:], package, level)
  File "<frozen importlib._bootstrap>", line 994, in _gcd_import
  File "<frozen importlib._bootstrap>", line 971, in _find_and_load
  File "<frozen importlib._bootstrap>", line 955, in _find_and_load_unlocked
  File "<frozen importlib._bootstrap>", line 665, in _load_unlocked
  File "<frozen importlib._bootstrap_external>", line 678, in exec_module
  File "<frozen importlib._bootstrap>", line 219, in _call_with_frames_removed
  File "/home/wercules/medreport/mrApp/urls.py", line 5, in <module>
    from . import views
  File "/home/wercules/medreport/mrApp/views.py", line 8, in <module>
    from .forms import PacienteForm, ProcurarPacienteForm
  File "/home/wercules/medreport/mrApp/forms.py", line 25, in <module>
    class AtendimentoForm(forms.Form):
  File "/home/wercules/medreport/mrApp/forms.py", line 26, in AtendimentoForm
    data_atendimento = form.DateField(label = 'Data de Nascimento', widget = forms.DateInput(attrs={'id':'data'}))
NameError: name 'form' is not defined

Performing system checks...

Watching for file changes with StatReloader
Exception in thread django-main-thread:
Traceback (most recent call last):
  File "/usr/lib64/python3.6/threading.py", line 916, in _bootstrap_inner
    self.run()
  File "/usr/lib64/python3.6/threading.py", line 864, in run
    self._target(*self._args, **self._kwargs)
  File "/home/wercules/.local/share/virtualenvs/medreport-3oUkA-aL/lib/python3.6/site-packages/django/utils/autoreload.py", line 54, in wrapper
    fn(*args, **kwargs)
  File "/home/wercules/.local/share/virtualenvs/medreport-3oUkA-aL/lib/python3.6/site-packages/django/core/management/commands/runserver.py", line 117, in inner_run
    self.check(display_num_errors=True)
  File "/home/wercules/.local/share/virtualenvs/medreport-3oUkA-aL/lib/python3.6/site-packages/django/core/management/base.py", line 390, in check
    include_deployment_checks=include_deployment_checks,
  File "/home/wercules/.local/share/virtualenvs/medreport-3oUkA-aL/lib/python3.6/site-packages/django/core/management/base.py", line 377, in _run_checks
    return checks.run_checks(**kwargs)
  File "/home/wercules/.local/share/virtualenvs/medreport-3oUkA-aL/lib/python3.6/site-packages/django/core/checks/registry.py", line 72, in run_checks
    new_errors = check(app_configs=app_configs)
  File "/home/wercules/.local/share/virtualenvs/medreport-3oUkA-aL/lib/python3.6/site-packages/django/core/checks/urls.py", line 40, in check_url_namespaces_unique
    all_namespaces = _load_all_namespaces(resolver)
  File "/home/wercules/.local/share/virtualenvs/medreport-3oUkA-aL/lib/python3.6/site-packages/django/core/checks/urls.py", line 57, in _load_all_namespaces
    url_patterns = getattr(resolver, 'url_patterns', [])
  File "/home/wercules/.local/share/virtualenvs/medreport-3oUkA-aL/lib/python3.6/site-packages/django/utils/functional.py", line 80, in __get__
    res = instance.__dict__[self.name] = self.func(instance)
  File "/home/wercules/.local/share/virtualenvs/medreport-3oUkA-aL/lib/python3.6/site-packages/django/urls/resolvers.py", line 579, in url_patterns
    patterns = getattr(self.urlconf_module, "urlpatterns", self.urlconf_module)
  File "/home/wercules/.local/share/virtualenvs/medreport-3oUkA-aL/lib/python3.6/site-packages/django/utils/functional.py", line 80, in __get__
    res = instance.__dict__[self.name] = self.func(instance)
  File "/home/wercules/.local/share/virtualenvs/medreport-3oUkA-aL/lib/python3.6/site-packages/django/urls/resolvers.py", line 572, in urlconf_module
    return import_module(self.urlconf_name)
  File "/home/wercules/.local/share/virtualenvs/medreport-3oUkA-aL/lib64/python3.6/importlib/__init__.py", line 126, in import_module
    return _bootstrap._gcd_import(name[level:], package, level)
  File "<frozen importlib._bootstrap>", line 994, in _gcd_import
  File "<frozen importlib._bootstrap>", line 971, in _find_and_load
  File "<frozen importlib._bootstrap>", line 955, in _find_and_load_unlocked
  File "<frozen importlib._bootstrap>", line 665, in _load_unlocked
  File "<frozen importlib._bootstrap_external>", line 678, in exec_module
  File "<frozen importlib._bootstrap>", line 219, in _call_with_frames_removed
  File "/home/wercules/medreport/mrProject/urls.py", line 20, in <module>
    path('mr/', include('mrApp.urls')),
  File "/home/wercules/.local/share/virtualenvs/medreport-3oUkA-aL/lib/python3.6/site-packages/django/urls/conf.py", line 34, in include
    urlconf_module = import_module(urlconf_module)
  File "/home/wercules/.local/share/virtualenvs/medreport-3oUkA-aL/lib64/python3.6/importlib/__init__.py", line 126, in import_module
    return _bootstrap._gcd_import(name[level:], package, level)
  File "<frozen importlib._bootstrap>", line 994, in _gcd_import
  File "<frozen importlib._bootstrap>", line 971, in _find_and_load
  File "<frozen importlib._bootstrap>", line 955, in _find_and_load_unlocked
  File "<frozen importlib._bootstrap>", line 665, in _load_unlocked
  File "<frozen importlib._bootstrap_external>", line 678, in exec_module
  File "<frozen importlib._bootstrap>", line 219, in _call_with_frames_removed
  File "/home/wercules/medreport/mrApp/urls.py", line 5, in <module>
    from . import views
  File "/home/wercules/medreport/mrApp/views.py", line 8, in <module>
    from .forms import PacienteForm, ProcurarPacienteForm
  File "/home/wercules/medreport/mrApp/forms.py", line 25, in <module>
    class AtendimentoForm(forms.Form):
  File "/home/wercules/medreport/mrApp/forms.py", line 26, in AtendimentoForm
    data_atendimento = form.DateField(label = 'Data de Nascimento', widget = forms.DateInput(attrs={'id':'data'}))
NameError: name 'form' is not defined

/home/wercules/medreport/mrApp/forms.py changed, reloading.
Performing system checks...

Watching for file changes with StatReloader
